Traceback (most recent call last):
  File "/w/home.27/ee/ugrad/jiayun/CS131/Project/./sample_submission/server.py", line 233, in <module>
    main()
  File "/w/home.27/ee/ugrad/jiayun/CS131/Project/./sample_submission/server.py", line 227, in main
    asyncio.run(server.run_forever())
  File "/usr/local/cs/Python-3.9.0/lib/python3.9/asyncio/runners.py", line 44, in run
    return loop.run_until_complete(main)
  File "/usr/local/cs/Python-3.9.0/lib/python3.9/asyncio/base_events.py", line 642, in run_until_complete
    return future.result()
  File "/w/home.27/ee/ugrad/jiayun/CS131/Project/./sample_submission/server.py", line 191, in run_forever
    server = await asyncio.start_server(self.handle_input, self.ip, self.port)
  File "/usr/local/cs/Python-3.9.0/lib/python3.9/asyncio/streams.py", line 94, in start_server
    return await loop.create_server(factory, host, port, **kwds)
  File "/usr/local/cs/Python-3.9.0/lib/python3.9/asyncio/base_events.py", line 1494, in create_server
    raise OSError(err.errno, 'error while attempting '
OSError: [Errno 98] error while attempting to bind on address ('127.0.0.1', 12441): address already in use
Traceback (most recent call last):
  File "/w/home.27/ee/ugrad/jiayun/CS131/Project/./sample_submission/server.py", line 233, in <module>
    main()
  File "/w/home.27/ee/ugrad/jiayun/CS131/Project/./sample_submission/server.py", line 227, in main
    asyncio.run(server.run_forever())
  File "/usr/local/cs/Python-3.9.0/lib/python3.9/asyncio/runners.py", line 44, in run
    return loop.run_until_complete(main)
  File "/usr/local/cs/Python-3.9.0/lib/python3.9/asyncio/base_events.py", line 642, in run_until_complete
    return future.result()
  File "/w/home.27/ee/ugrad/jiayun/CS131/Project/./sample_submission/server.py", line 191, in run_forever
    server = await asyncio.start_server(self.handle_input, self.ip, self.port)
  File "/usr/local/cs/Python-3.9.0/lib/python3.9/asyncio/streams.py", line 94, in start_server
    return await loop.create_server(factory, host, port, **kwds)
  File "/usr/local/cs/Python-3.9.0/lib/python3.9/asyncio/base_events.py", line 1494, in create_server
    raise OSError(err.errno, 'error while attempting '
OSError: [Errno 98] error while attempting to bind on address ('127.0.0.1', 12442): address already in use
Traceback (most recent call last):
  File "/w/home.27/ee/ugrad/jiayun/CS131/Project/./sample_submission/server.py", line 233, in <module>
    main()
  File "/w/home.27/ee/ugrad/jiayun/CS131/Project/./sample_submission/server.py", line 227, in main
    asyncio.run(server.run_forever())
  File "/usr/local/cs/Python-3.9.0/lib/python3.9/asyncio/runners.py", line 44, in run
    return loop.run_until_complete(main)
  File "/usr/local/cs/Python-3.9.0/lib/python3.9/asyncio/base_events.py", line 642, in run_until_complete
    return future.result()
  File "/w/home.27/ee/ugrad/jiayun/CS131/Project/./sample_submission/server.py", line 191, in run_forever
    server = await asyncio.start_server(self.handle_input, self.ip, self.port)
  File "/usr/local/cs/Python-3.9.0/lib/python3.9/asyncio/streams.py", line 94, in start_server
    return await loop.create_server(factory, host, port, **kwds)
  File "/usr/local/cs/Python-3.9.0/lib/python3.9/asyncio/base_events.py", line 1494, in create_server
    raise OSError(err.errno, 'error while attempting '
OSError: [Errno 98] error while attempting to bind on address ('127.0.0.1', 12443): address already in use
Traceback (most recent call last):
  File "/w/home.27/ee/ugrad/jiayun/CS131/Project/./sample_submission/server.py", line 233, in <module>
    main()
  File "/w/home.27/ee/ugrad/jiayun/CS131/Project/./sample_submission/server.py", line 227, in main
    asyncio.run(server.run_forever())
  File "/usr/local/cs/Python-3.9.0/lib/python3.9/asyncio/runners.py", line 44, in run
    return loop.run_until_complete(main)
  File "/usr/local/cs/Python-3.9.0/lib/python3.9/asyncio/base_events.py", line 642, in run_until_complete
    return future.result()
  File "/w/home.27/ee/ugrad/jiayun/CS131/Project/./sample_submission/server.py", line 191, in run_forever
    server = await asyncio.start_server(self.handle_input, self.ip, self.port)
  File "/usr/local/cs/Python-3.9.0/lib/python3.9/asyncio/streams.py", line 94, in start_server
    return await loop.create_server(factory, host, port, **kwds)
  File "/usr/local/cs/Python-3.9.0/lib/python3.9/asyncio/base_events.py", line 1494, in create_server
    raise OSError(err.errno, 'error while attempting '
OSError: [Errno 98] error while attempting to bind on address ('127.0.0.1', 12444): address already in use
Traceback (most recent call last):
  File "/w/home.27/ee/ugrad/jiayun/CS131/Project/./sample_submission/server.py", line 233, in <module>
    main()
  File "/w/home.27/ee/ugrad/jiayun/CS131/Project/./sample_submission/server.py", line 227, in main
    asyncio.run(server.run_forever())
  File "/usr/local/cs/Python-3.9.0/lib/python3.9/asyncio/runners.py", line 44, in run
    return loop.run_until_complete(main)
  File "/usr/local/cs/Python-3.9.0/lib/python3.9/asyncio/base_events.py", line 642, in run_until_complete
    return future.result()
  File "/w/home.27/ee/ugrad/jiayun/CS131/Project/./sample_submission/server.py", line 191, in run_forever
    server = await asyncio.start_server(self.handle_input, self.ip, self.port)
  File "/usr/local/cs/Python-3.9.0/lib/python3.9/asyncio/streams.py", line 94, in start_server
    return await loop.create_server(factory, host, port, **kwds)
  File "/usr/local/cs/Python-3.9.0/lib/python3.9/asyncio/base_events.py", line 1494, in create_server
    raise OSError(err.errno, 'error while attempting '
OSError: [Errno 98] error while attempting to bind on address ('127.0.0.1', 12440): address already in use
Traceback (most recent call last):
  File "/w/home.27/ee/ugrad/jiayun/CS131/Project/./sample_submission/server.py", line 233, in <module>
    main()
  File "/w/home.27/ee/ugrad/jiayun/CS131/Project/./sample_submission/server.py", line 227, in main
    asyncio.run(server.run_forever())
  File "/usr/local/cs/Python-3.9.0/lib/python3.9/asyncio/runners.py", line 44, in run
    return loop.run_until_complete(main)
  File "/usr/local/cs/Python-3.9.0/lib/python3.9/asyncio/base_events.py", line 642, in run_until_complete
    return future.result()
  File "/w/home.27/ee/ugrad/jiayun/CS131/Project/./sample_submission/server.py", line 191, in run_forever
    server = await asyncio.start_server(self.handle_input, self.ip, self.port)
  File "/usr/local/cs/Python-3.9.0/lib/python3.9/asyncio/streams.py", line 94, in start_server
    return await loop.create_server(factory, host, port, **kwds)
  File "/usr/local/cs/Python-3.9.0/lib/python3.9/asyncio/base_events.py", line 1494, in create_server
    raise OSError(err.errno, 'error while attempting '
OSError: [Errno 98] error while attempting to bind on address ('127.0.0.1', 12442): address already in use
Traceback (most recent call last):
  File "/w/home.27/ee/ugrad/jiayun/CS131/Project/./sample_submission/server.py", line 233, in <module>
    main()
  File "/w/home.27/ee/ugrad/jiayun/CS131/Project/./sample_submission/server.py", line 227, in main
    asyncio.run(server.run_forever())
  File "/usr/local/cs/Python-3.9.0/lib/python3.9/asyncio/runners.py", line 44, in run
    return loop.run_until_complete(main)
  File "/usr/local/cs/Python-3.9.0/lib/python3.9/asyncio/base_events.py", line 642, in run_until_complete
    return future.result()
  File "/w/home.27/ee/ugrad/jiayun/CS131/Project/./sample_submission/server.py", line 191, in run_forever
    server = await asyncio.start_server(self.handle_input, self.ip, self.port)
  File "/usr/local/cs/Python-3.9.0/lib/python3.9/asyncio/streams.py", line 94, in start_server
    return await loop.create_server(factory, host, port, **kwds)
  File "/usr/local/cs/Python-3.9.0/lib/python3.9/asyncio/base_events.py", line 1494, in create_server
    raise OSError(err.errno, 'error while attempting '
OSError: [Errno 98] error while attempting to bind on address ('127.0.0.1', 12443): address already in use
Traceback (most recent call last):
  File "/w/home.27/ee/ugrad/jiayun/CS131/Project/./sample_submission/server.py", line 233, in <module>
    main()
  File "/w/home.27/ee/ugrad/jiayun/CS131/Project/./sample_submission/server.py", line 227, in main
    asyncio.run(server.run_forever())
  File "/usr/local/cs/Python-3.9.0/lib/python3.9/asyncio/runners.py", line 44, in run
    return loop.run_until_complete(main)
  File "/usr/local/cs/Python-3.9.0/lib/python3.9/asyncio/base_events.py", line 642, in run_until_complete
    return future.result()
  File "/w/home.27/ee/ugrad/jiayun/CS131/Project/./sample_submission/server.py", line 191, in run_forever
    server = await asyncio.start_server(self.handle_input, self.ip, self.port)
  File "/usr/local/cs/Python-3.9.0/lib/python3.9/asyncio/streams.py", line 94, in start_server
    return await loop.create_server(factory, host, port, **kwds)
  File "/usr/local/cs/Python-3.9.0/lib/python3.9/asyncio/base_events.py", line 1494, in create_server
    raise OSError(err.errno, 'error while attempting '
OSError: [Errno 98] error while attempting to bind on address ('127.0.0.1', 12444): address already in use
Traceback (most recent call last):
  File "/w/home.27/ee/ugrad/jiayun/CS131/Project/./sample_submission/server.py", line 233, in <module>
    main()
  File "/w/home.27/ee/ugrad/jiayun/CS131/Project/./sample_submission/server.py", line 227, in main
    asyncio.run(server.run_forever())
  File "/usr/local/cs/Python-3.9.0/lib/python3.9/asyncio/runners.py", line 44, in run
    return loop.run_until_complete(main)
  File "/usr/local/cs/Python-3.9.0/lib/python3.9/asyncio/base_events.py", line 642, in run_until_complete
    return future.result()
  File "/w/home.27/ee/ugrad/jiayun/CS131/Project/./sample_submission/server.py", line 191, in run_forever
    server = await asyncio.start_server(self.handle_input, self.ip, self.port)
  File "/usr/local/cs/Python-3.9.0/lib/python3.9/asyncio/streams.py", line 94, in start_server
    return await loop.create_server(factory, host, port, **kwds)
  File "/usr/local/cs/Python-3.9.0/lib/python3.9/asyncio/base_events.py", line 1494, in create_server
    raise OSError(err.errno, 'error while attempting '
OSError: [Errno 98] error while attempting to bind on address ('127.0.0.1', 12441): address already in use
Traceback (most recent call last):
  File "/w/home.27/ee/ugrad/jiayun/CS131/Project/./sample_submission/server.py", line 233, in <module>
    main()
  File "/w/home.27/ee/ugrad/jiayun/CS131/Project/./sample_submission/server.py", line 227, in main
    asyncio.run(server.run_forever())
  File "/usr/local/cs/Python-3.9.0/lib/python3.9/asyncio/runners.py", line 44, in run
    return loop.run_until_complete(main)
  File "/usr/local/cs/Python-3.9.0/lib/python3.9/asyncio/base_events.py", line 642, in run_until_complete
    return future.result()
  File "/w/home.27/ee/ugrad/jiayun/CS131/Project/./sample_submission/server.py", line 191, in run_forever
    server = await asyncio.start_server(self.handle_input, self.ip, self.port)
  File "/usr/local/cs/Python-3.9.0/lib/python3.9/asyncio/streams.py", line 94, in start_server
    return await loop.create_server(factory, host, port, **kwds)
  File "/usr/local/cs/Python-3.9.0/lib/python3.9/asyncio/base_events.py", line 1494, in create_server
    raise OSError(err.errno, 'error while attempting '
OSError: [Errno 98] error while attempting to bind on address ('127.0.0.1', 12443): address already in use
Traceback (most recent call last):
  File "/w/home.27/ee/ugrad/jiayun/CS131/Project/./sample_submission/server.py", line 233, in <module>
    main()
  File "/w/home.27/ee/ugrad/jiayun/CS131/Project/./sample_submission/server.py", line 227, in main
    asyncio.run(server.run_forever())
  File "/usr/local/cs/Python-3.9.0/lib/python3.9/asyncio/runners.py", line 44, in run
    return loop.run_until_complete(main)
  File "/usr/local/cs/Python-3.9.0/lib/python3.9/asyncio/base_events.py", line 642, in run_until_complete
    return future.result()
  File "/w/home.27/ee/ugrad/jiayun/CS131/Project/./sample_submission/server.py", line 191, in run_forever
    server = await asyncio.start_server(self.handle_input, self.ip, self.port)
  File "/usr/local/cs/Python-3.9.0/lib/python3.9/asyncio/streams.py", line 94, in start_server
    return await loop.create_server(factory, host, port, **kwds)
  File "/usr/local/cs/Python-3.9.0/lib/python3.9/asyncio/base_events.py", line 1494, in create_server
    raise OSError(err.errno, 'error while attempting '
OSError: [Errno 98] error while attempting to bind on address ('127.0.0.1', 12444): address already in use
Traceback (most recent call last):
  File "/w/home.27/ee/ugrad/jiayun/CS131/Project/./sample_submission/server.py", line 233, in <module>
    main()
  File "/w/home.27/ee/ugrad/jiayun/CS131/Project/./sample_submission/server.py", line 227, in main
    asyncio.run(server.run_forever())
  File "/usr/local/cs/Python-3.9.0/lib/python3.9/asyncio/runners.py", line 44, in run
    return loop.run_until_complete(main)
  File "/usr/local/cs/Python-3.9.0/lib/python3.9/asyncio/base_events.py", line 642, in run_until_complete
    return future.result()
  File "/w/home.27/ee/ugrad/jiayun/CS131/Project/./sample_submission/server.py", line 191, in run_forever
    server = await asyncio.start_server(self.handle_input, self.ip, self.port)
  File "/usr/local/cs/Python-3.9.0/lib/python3.9/asyncio/streams.py", line 94, in start_server
    return await loop.create_server(factory, host, port, **kwds)
  File "/usr/local/cs/Python-3.9.0/lib/python3.9/asyncio/base_events.py", line 1494, in create_server
    raise OSError(err.errno, 'error while attempting '
OSError: [Errno 98] error while attempting to bind on address ('127.0.0.1', 12442): address already in use
Traceback (most recent call last):
  File "/w/home.27/ee/ugrad/jiayun/CS131/Project/./sample_submission/server.py", line 233, in <module>
    main()
  File "/w/home.27/ee/ugrad/jiayun/CS131/Project/./sample_submission/server.py", line 227, in main
    asyncio.run(server.run_forever())
  File "/usr/local/cs/Python-3.9.0/lib/python3.9/asyncio/runners.py", line 44, in run
    return loop.run_until_complete(main)
  File "/usr/local/cs/Python-3.9.0/lib/python3.9/asyncio/base_events.py", line 642, in run_until_complete
    return future.result()
  File "/w/home.27/ee/ugrad/jiayun/CS131/Project/./sample_submission/server.py", line 191, in run_forever
    server = await asyncio.start_server(self.handle_input, self.ip, self.port)
  File "/usr/local/cs/Python-3.9.0/lib/python3.9/asyncio/streams.py", line 94, in start_server
    return await loop.create_server(factory, host, port, **kwds)
  File "/usr/local/cs/Python-3.9.0/lib/python3.9/asyncio/base_events.py", line 1494, in create_server
    raise OSError(err.errno, 'error while attempting '
OSError: [Errno 98] error while attempting to bind on address ('127.0.0.1', 12444): address already in use
Traceback (most recent call last):
  File "/w/home.27/ee/ugrad/jiayun/CS131/Project/./sample_submission/server.py", line 233, in <module>
    main()
  File "/w/home.27/ee/ugrad/jiayun/CS131/Project/./sample_submission/server.py", line 227, in main
    asyncio.run(server.run_forever())
  File "/usr/local/cs/Python-3.9.0/lib/python3.9/asyncio/runners.py", line 44, in run
    return loop.run_until_complete(main)
  File "/usr/local/cs/Python-3.9.0/lib/python3.9/asyncio/base_events.py", line 642, in run_until_complete
    return future.result()
  File "/w/home.27/ee/ugrad/jiayun/CS131/Project/./sample_submission/server.py", line 191, in run_forever
    server = await asyncio.start_server(self.handle_input, self.ip, self.port)
  File "/usr/local/cs/Python-3.9.0/lib/python3.9/asyncio/streams.py", line 94, in start_server
    return await loop.create_server(factory, host, port, **kwds)
  File "/usr/local/cs/Python-3.9.0/lib/python3.9/asyncio/base_events.py", line 1494, in create_server
    raise OSError(err.errno, 'error while attempting '
OSError: [Errno 98] error while attempting to bind on address ('127.0.0.1', 12443): address already in use
Traceback (most recent call last):
  File "/w/home.27/ee/ugrad/jiayun/CS131/Project/./sample_submission/server.py", line 262, in <module>
    main()
  File "/w/home.27/ee/ugrad/jiayun/CS131/Project/./sample_submission/server.py", line 230, in main
    if not serverName in serverNameToPort:
NameError: name 'serverNameToPort' is not defined
Traceback (most recent call last):
  File "/w/home.27/ee/ugrad/jiayun/CS131/Project/./sample_submission/server.py", line 262, in <module>
    main()
  File "/w/home.27/ee/ugrad/jiayun/CS131/Project/./sample_submission/server.py", line 230, in main
    if not serverName in serverNameToPort:
NameError: name 'serverNameToPort' is not defined
Traceback (most recent call last):
  File "/w/home.27/ee/ugrad/jiayun/CS131/Project/./sample_submission/server.py", line 262, in <module>
    main()
  File "/w/home.27/ee/ugrad/jiayun/CS131/Project/./sample_submission/server.py", line 230, in main
    if not serverName in serverNameToPort:
NameError: name 'serverNameToPort' is not defined
Traceback (most recent call last):
  File "/w/home.27/ee/ugrad/jiayun/CS131/Project/./sample_submission/server.py", line 262, in <module>
    main()
  File "/w/home.27/ee/ugrad/jiayun/CS131/Project/./sample_submission/server.py", line 230, in main
    if not serverName in serverNameToPort:
NameError: name 'serverNameToPort' is not defined
Traceback (most recent call last):
  File "/w/home.27/ee/ugrad/jiayun/CS131/Project/./sample_submission/server.py", line 262, in <module>
    main()
  File "/w/home.27/ee/ugrad/jiayun/CS131/Project/./sample_submission/server.py", line 230, in main
    if not serverName in serverNameToPort:
NameError: name 'serverNameToPort' is not defined
Traceback (most recent call last):
  File "/w/home.27/ee/ugrad/jiayun/CS131/Project/./sample_submission/server.py", line 262, in <module>
    main()
  File "/w/home.27/ee/ugrad/jiayun/CS131/Project/./sample_submission/server.py", line 235, in main
    logging.basicConfig(filename="{}Server.log".format(args.serverName), 
AttributeError: 'Namespace' object has no attribute 'serverName'
Traceback (most recent call last):
  File "/w/home.27/ee/ugrad/jiayun/CS131/Project/./sample_submission/server.py", line 262, in <module>
    main()
  File "/w/home.27/ee/ugrad/jiayun/CS131/Project/./sample_submission/server.py", line 235, in main
    logging.basicConfig(filename="{}Server.log".format(args.serverName), 
AttributeError: 'Namespace' object has no attribute 'serverName'
Traceback (most recent call last):
  File "/w/home.27/ee/ugrad/jiayun/CS131/Project/./sample_submission/server.py", line 262, in <module>
    main()
  File "/w/home.27/ee/ugrad/jiayun/CS131/Project/./sample_submission/server.py", line 235, in main
    logging.basicConfig(filename="{}Server.log".format(args.serverName), 
AttributeError: 'Namespace' object has no attribute 'serverName'
Traceback (most recent call last):
  File "/w/home.27/ee/ugrad/jiayun/CS131/Project/./sample_submission/server.py", line 262, in <module>
    main()
  File "/w/home.27/ee/ugrad/jiayun/CS131/Project/./sample_submission/server.py", line 235, in main
    logging.basicConfig(filename="{}Server.log".format(args.serverName), 
AttributeError: 'Namespace' object has no attribute 'serverName'
Traceback (most recent call last):
  File "/w/home.27/ee/ugrad/jiayun/CS131/Project/./sample_submission/server.py", line 262, in <module>
    main()
  File "/w/home.27/ee/ugrad/jiayun/CS131/Project/./sample_submission/server.py", line 235, in main
    logging.basicConfig(filename="{}Server.log".format(args.serverName), 
AttributeError: 'Namespace' object has no attribute 'serverName'
  File "/w/home.27/ee/ugrad/jiayun/CS131/Project/./sample_submission/server.py", line 17
    "Smith", 12442,
           ^
SyntaxError: invalid syntax
  File "/w/home.27/ee/ugrad/jiayun/CS131/Project/./sample_submission/server.py", line 17
    "Smith", 12442,
           ^
SyntaxError: invalid syntax
  File "/w/home.27/ee/ugrad/jiayun/CS131/Project/./sample_submission/server.py", line 17
    "Smith", 12442,
           ^
SyntaxError: invalid syntax
  File "/w/home.27/ee/ugrad/jiayun/CS131/Project/./sample_submission/server.py", line 17
    "Smith", 12442,
           ^
SyntaxError: invalid syntax
  File "/w/home.27/ee/ugrad/jiayun/CS131/Project/./sample_submission/server.py", line 17
    "Smith", 12442,
           ^
SyntaxError: invalid syntax
  File "/w/home.27/ee/ugrad/jiayun/CS131/Project/./sample_submission/server.py", line 17
    "Smith", 12442,
           ^
SyntaxError: invalid syntax
  File "/w/home.27/ee/ugrad/jiayun/CS131/Project/./sample_submission/server.py", line 17
    "Smith", 12442,
           ^
SyntaxError: invalid syntax
  File "/w/home.27/ee/ugrad/jiayun/CS131/Project/./sample_submission/server.py", line 17
    "Smith", 12442,
           ^
SyntaxError: invalid syntax
  File "/w/home.27/ee/ugrad/jiayun/CS131/Project/./sample_submission/server.py", line 17
    "Smith", 12442,
           ^
SyntaxError: invalid syntax
  File "/w/home.27/ee/ugrad/jiayun/CS131/Project/./sample_submission/server.py", line 17
    "Smith", 12442,
           ^
SyntaxError: invalid syntax
  File "/w/home.27/ee/ugrad/jiayun/CS131/Project/./sample_submission/server.py", line 17
    "Smith", 12442,
           ^
SyntaxError: invalid syntax
  File "/w/home.27/ee/ugrad/jiayun/CS131/Project/./sample_submission/server.py", line 17
    "Smith", 12442,
           ^
SyntaxError: invalid syntax
  File "/w/home.27/ee/ugrad/jiayun/CS131/Project/./sample_submission/server.py", line 17
    "Smith", 12442,
           ^
SyntaxError: invalid syntax
  File "/w/home.27/ee/ugrad/jiayun/CS131/Project/./sample_submission/server.py", line 17
    "Smith", 12442,
           ^
SyntaxError: invalid syntax
  File "/w/home.27/ee/ugrad/jiayun/CS131/Project/./sample_submission/server.py", line 17
    "Smith", 12442,
           ^
SyntaxError: invalid syntax
  File "/w/home.27/ee/ugrad/jiayun/CS131/Project/./sample_submission/server.py", line 17
    "Smith", 12442,
           ^
SyntaxError: invalid syntax
  File "/w/home.27/ee/ugrad/jiayun/CS131/Project/./sample_submission/server.py", line 17
    "Smith", 12442,
           ^
SyntaxError: invalid syntax
  File "/w/home.27/ee/ugrad/jiayun/CS131/Project/./sample_submission/server.py", line 17
    "Smith", 12442,
           ^
SyntaxError: invalid syntax
  File "/w/home.27/ee/ugrad/jiayun/CS131/Project/./sample_submission/server.py", line 17
    "Smith", 12442,
           ^
SyntaxError: invalid syntax
  File "/w/home.27/ee/ugrad/jiayun/CS131/Project/./sample_submission/server.py", line 17
    "Smith", 12442,
           ^
SyntaxError: invalid syntax
  File "/w/home.27/ee/ugrad/jiayun/CS131/Project/./sample_submission/server.py", line 17
    "Smith", 12442,
           ^
SyntaxError: invalid syntax
  File "/w/home.27/ee/ugrad/jiayun/CS131/Project/./sample_submission/server.py", line 17
    "Smith", 12442,
           ^
SyntaxError: invalid syntax
  File "/w/home.27/ee/ugrad/jiayun/CS131/Project/./sample_submission/server.py", line 17
    "Smith", 12442,
           ^
SyntaxError: invalid syntax
  File "/w/home.27/ee/ugrad/jiayun/CS131/Project/./sample_submission/server.py", line 17
    "Smith", 12442,
           ^
SyntaxError: invalid syntax
  File "/w/home.27/ee/ugrad/jiayun/CS131/Project/./sample_submission/server.py", line 17
    "Smith", 12442,
           ^
SyntaxError: invalid syntax
Traceback (most recent call last):
  File "/w/home.27/ee/ugrad/jiayun/CS131/Project/./sample_submission/server.py", line 247, in <module>
    main()
  File "/w/home.27/ee/ugrad/jiayun/CS131/Project/./sample_submission/server.py", line 242, in main
    asyncio.run(server.run_forever())
  File "/usr/local/cs/Python-3.9.0/lib/python3.9/asyncio/runners.py", line 44, in run
    return loop.run_until_complete(main)
  File "/usr/local/cs/Python-3.9.0/lib/python3.9/asyncio/base_events.py", line 642, in run_until_complete
    return future.result()
  File "/w/home.27/ee/ugrad/jiayun/CS131/Project/./sample_submission/server.py", line 191, in run_forever
    server = await asyncio.start_server(self.handle_input, self.ip, self.port)
  File "/usr/local/cs/Python-3.9.0/lib/python3.9/asyncio/streams.py", line 94, in start_server
    return await loop.create_server(factory, host, port, **kwds)
  File "/usr/local/cs/Python-3.9.0/lib/python3.9/asyncio/base_events.py", line 1494, in create_server
    raise OSError(err.errno, 'error while attempting '
OSError: [Errno 98] error while attempting to bind on address ('127.0.0.1', 12441): address already in use
Traceback (most recent call last):
  File "/w/home.27/ee/ugrad/jiayun/CS131/Project/./sample_submission/server.py", line 247, in <module>
    main()
  File "/w/home.27/ee/ugrad/jiayun/CS131/Project/./sample_submission/server.py", line 242, in main
    asyncio.run(server.run_forever())
  File "/usr/local/cs/Python-3.9.0/lib/python3.9/asyncio/runners.py", line 44, in run
    return loop.run_until_complete(main)
  File "/usr/local/cs/Python-3.9.0/lib/python3.9/asyncio/base_events.py", line 642, in run_until_complete
    return future.result()
  File "/w/home.27/ee/ugrad/jiayun/CS131/Project/./sample_submission/server.py", line 191, in run_forever
    server = await asyncio.start_server(self.handle_input, self.ip, self.port)
  File "/usr/local/cs/Python-3.9.0/lib/python3.9/asyncio/streams.py", line 94, in start_server
    return await loop.create_server(factory, host, port, **kwds)
  File "/usr/local/cs/Python-3.9.0/lib/python3.9/asyncio/base_events.py", line 1494, in create_server
    raise OSError(err.errno, 'error while attempting '
OSError: [Errno 98] error while attempting to bind on address ('127.0.0.1', 12442): address already in use
Traceback (most recent call last):
  File "/w/home.27/ee/ugrad/jiayun/CS131/Project/./sample_submission/server.py", line 247, in <module>
    main()
  File "/w/home.27/ee/ugrad/jiayun/CS131/Project/./sample_submission/server.py", line 242, in main
    asyncio.run(server.run_forever())
  File "/usr/local/cs/Python-3.9.0/lib/python3.9/asyncio/runners.py", line 44, in run
    return loop.run_until_complete(main)
  File "/usr/local/cs/Python-3.9.0/lib/python3.9/asyncio/base_events.py", line 642, in run_until_complete
    return future.result()
  File "/w/home.27/ee/ugrad/jiayun/CS131/Project/./sample_submission/server.py", line 191, in run_forever
    server = await asyncio.start_server(self.handle_input, self.ip, self.port)
  File "/usr/local/cs/Python-3.9.0/lib/python3.9/asyncio/streams.py", line 94, in start_server
    return await loop.create_server(factory, host, port, **kwds)
  File "/usr/local/cs/Python-3.9.0/lib/python3.9/asyncio/base_events.py", line 1494, in create_server
    raise OSError(err.errno, 'error while attempting '
OSError: [Errno 98] error while attempting to bind on address ('127.0.0.1', 12443): address already in use
Traceback (most recent call last):
  File "/w/home.27/ee/ugrad/jiayun/CS131/Project/./sample_submission/server.py", line 247, in <module>
    main()
  File "/w/home.27/ee/ugrad/jiayun/CS131/Project/./sample_submission/server.py", line 242, in main
    asyncio.run(server.run_forever())
  File "/usr/local/cs/Python-3.9.0/lib/python3.9/asyncio/runners.py", line 44, in run
    return loop.run_until_complete(main)
  File "/usr/local/cs/Python-3.9.0/lib/python3.9/asyncio/base_events.py", line 642, in run_until_complete
    return future.result()
  File "/w/home.27/ee/ugrad/jiayun/CS131/Project/./sample_submission/server.py", line 191, in run_forever
    server = await asyncio.start_server(self.handle_input, self.ip, self.port)
  File "/usr/local/cs/Python-3.9.0/lib/python3.9/asyncio/streams.py", line 94, in start_server
    return await loop.create_server(factory, host, port, **kwds)
  File "/usr/local/cs/Python-3.9.0/lib/python3.9/asyncio/base_events.py", line 1494, in create_server
    raise OSError(err.errno, 'error while attempting '
OSError: [Errno 98] error while attempting to bind on address ('127.0.0.1', 12444): address already in use
Traceback (most recent call last):
  File "/w/home.27/ee/ugrad/jiayun/CS131/Project/./sample_submission/server.py", line 247, in <module>
    main()
  File "/w/home.27/ee/ugrad/jiayun/CS131/Project/./sample_submission/server.py", line 242, in main
    asyncio.run(server.run_forever())
  File "/usr/local/cs/Python-3.9.0/lib/python3.9/asyncio/runners.py", line 44, in run
    return loop.run_until_complete(main)
  File "/usr/local/cs/Python-3.9.0/lib/python3.9/asyncio/base_events.py", line 642, in run_until_complete
    return future.result()
  File "/w/home.27/ee/ugrad/jiayun/CS131/Project/./sample_submission/server.py", line 191, in run_forever
    server = await asyncio.start_server(self.handle_input, self.ip, self.port)
  File "/usr/local/cs/Python-3.9.0/lib/python3.9/asyncio/streams.py", line 94, in start_server
    return await loop.create_server(factory, host, port, **kwds)
  File "/usr/local/cs/Python-3.9.0/lib/python3.9/asyncio/base_events.py", line 1494, in create_server
    raise OSError(err.errno, 'error while attempting '
OSError: [Errno 98] error while attempting to bind on address ('127.0.0.1', 12440): address already in use
Traceback (most recent call last):
  File "/w/home.27/ee/ugrad/jiayun/CS131/Project/./sample_submission/server.py", line 247, in <module>
    main()
  File "/w/home.27/ee/ugrad/jiayun/CS131/Project/./sample_submission/server.py", line 242, in main
    asyncio.run(server.run_forever())
  File "/usr/local/cs/Python-3.9.0/lib/python3.9/asyncio/runners.py", line 44, in run
    return loop.run_until_complete(main)
  File "/usr/local/cs/Python-3.9.0/lib/python3.9/asyncio/base_events.py", line 642, in run_until_complete
    return future.result()
  File "/w/home.27/ee/ugrad/jiayun/CS131/Project/./sample_submission/server.py", line 191, in run_forever
    server = await asyncio.start_server(self.handle_input, self.ip, self.port)
  File "/usr/local/cs/Python-3.9.0/lib/python3.9/asyncio/streams.py", line 94, in start_server
    return await loop.create_server(factory, host, port, **kwds)
  File "/usr/local/cs/Python-3.9.0/lib/python3.9/asyncio/base_events.py", line 1494, in create_server
    raise OSError(err.errno, 'error while attempting '
OSError: [Errno 98] error while attempting to bind on address ('127.0.0.1', 12442): address already in use
Traceback (most recent call last):
  File "/w/home.27/ee/ugrad/jiayun/CS131/Project/./sample_submission/server.py", line 247, in <module>
    main()
  File "/w/home.27/ee/ugrad/jiayun/CS131/Project/./sample_submission/server.py", line 242, in main
    asyncio.run(server.run_forever())
  File "/usr/local/cs/Python-3.9.0/lib/python3.9/asyncio/runners.py", line 44, in run
    return loop.run_until_complete(main)
  File "/usr/local/cs/Python-3.9.0/lib/python3.9/asyncio/base_events.py", line 642, in run_until_complete
    return future.result()
  File "/w/home.27/ee/ugrad/jiayun/CS131/Project/./sample_submission/server.py", line 191, in run_forever
    server = await asyncio.start_server(self.handle_input, self.ip, self.port)
  File "/usr/local/cs/Python-3.9.0/lib/python3.9/asyncio/streams.py", line 94, in start_server
    return await loop.create_server(factory, host, port, **kwds)
  File "/usr/local/cs/Python-3.9.0/lib/python3.9/asyncio/base_events.py", line 1494, in create_server
    raise OSError(err.errno, 'error while attempting '
OSError: [Errno 98] error while attempting to bind on address ('127.0.0.1', 12443): address already in use
Traceback (most recent call last):
  File "/w/home.27/ee/ugrad/jiayun/CS131/Project/./sample_submission/server.py", line 247, in <module>
    main()
  File "/w/home.27/ee/ugrad/jiayun/CS131/Project/./sample_submission/server.py", line 242, in main
    asyncio.run(server.run_forever())
  File "/usr/local/cs/Python-3.9.0/lib/python3.9/asyncio/runners.py", line 44, in run
    return loop.run_until_complete(main)
  File "/usr/local/cs/Python-3.9.0/lib/python3.9/asyncio/base_events.py", line 642, in run_until_complete
    return future.result()
  File "/w/home.27/ee/ugrad/jiayun/CS131/Project/./sample_submission/server.py", line 191, in run_forever
    server = await asyncio.start_server(self.handle_input, self.ip, self.port)
  File "/usr/local/cs/Python-3.9.0/lib/python3.9/asyncio/streams.py", line 94, in start_server
    return await loop.create_server(factory, host, port, **kwds)
  File "/usr/local/cs/Python-3.9.0/lib/python3.9/asyncio/base_events.py", line 1494, in create_server
    raise OSError(err.errno, 'error while attempting '
OSError: [Errno 98] error while attempting to bind on address ('127.0.0.1', 12444): address already in use
Traceback (most recent call last):
  File "/w/home.27/ee/ugrad/jiayun/CS131/Project/./sample_submission/server.py", line 247, in <module>
    main()
  File "/w/home.27/ee/ugrad/jiayun/CS131/Project/./sample_submission/server.py", line 242, in main
    asyncio.run(server.run_forever())
  File "/usr/local/cs/Python-3.9.0/lib/python3.9/asyncio/runners.py", line 44, in run
    return loop.run_until_complete(main)
  File "/usr/local/cs/Python-3.9.0/lib/python3.9/asyncio/base_events.py", line 642, in run_until_complete
    return future.result()
  File "/w/home.27/ee/ugrad/jiayun/CS131/Project/./sample_submission/server.py", line 191, in run_forever
    server = await asyncio.start_server(self.handle_input, self.ip, self.port)
  File "/usr/local/cs/Python-3.9.0/lib/python3.9/asyncio/streams.py", line 94, in start_server
    return await loop.create_server(factory, host, port, **kwds)
  File "/usr/local/cs/Python-3.9.0/lib/python3.9/asyncio/base_events.py", line 1494, in create_server
    raise OSError(err.errno, 'error while attempting '
OSError: [Errno 98] error while attempting to bind on address ('127.0.0.1', 12441): address already in use
Traceback (most recent call last):
  File "/w/home.27/ee/ugrad/jiayun/CS131/Project/./sample_submission/server.py", line 247, in <module>
    main()
  File "/w/home.27/ee/ugrad/jiayun/CS131/Project/./sample_submission/server.py", line 242, in main
    asyncio.run(server.run_forever())
  File "/usr/local/cs/Python-3.9.0/lib/python3.9/asyncio/runners.py", line 44, in run
    return loop.run_until_complete(main)
  File "/usr/local/cs/Python-3.9.0/lib/python3.9/asyncio/base_events.py", line 642, in run_until_complete
    return future.result()
  File "/w/home.27/ee/ugrad/jiayun/CS131/Project/./sample_submission/server.py", line 191, in run_forever
    server = await asyncio.start_server(self.handle_input, self.ip, self.port)
  File "/usr/local/cs/Python-3.9.0/lib/python3.9/asyncio/streams.py", line 94, in start_server
    return await loop.create_server(factory, host, port, **kwds)
  File "/usr/local/cs/Python-3.9.0/lib/python3.9/asyncio/base_events.py", line 1494, in create_server
    raise OSError(err.errno, 'error while attempting '
OSError: [Errno 98] error while attempting to bind on address ('127.0.0.1', 12443): address already in use
Traceback (most recent call last):
  File "/w/home.27/ee/ugrad/jiayun/CS131/Project/./sample_submission/server.py", line 247, in <module>
    main()
  File "/w/home.27/ee/ugrad/jiayun/CS131/Project/./sample_submission/server.py", line 242, in main
    asyncio.run(server.run_forever())
  File "/usr/local/cs/Python-3.9.0/lib/python3.9/asyncio/runners.py", line 44, in run
    return loop.run_until_complete(main)
  File "/usr/local/cs/Python-3.9.0/lib/python3.9/asyncio/base_events.py", line 642, in run_until_complete
    return future.result()
  File "/w/home.27/ee/ugrad/jiayun/CS131/Project/./sample_submission/server.py", line 191, in run_forever
    server = await asyncio.start_server(self.handle_input, self.ip, self.port)
  File "/usr/local/cs/Python-3.9.0/lib/python3.9/asyncio/streams.py", line 94, in start_server
    return await loop.create_server(factory, host, port, **kwds)
  File "/usr/local/cs/Python-3.9.0/lib/python3.9/asyncio/base_events.py", line 1494, in create_server
    raise OSError(err.errno, 'error while attempting '
OSError: [Errno 98] error while attempting to bind on address ('127.0.0.1', 12444): address already in use
Traceback (most recent call last):
  File "/w/home.27/ee/ugrad/jiayun/CS131/Project/./sample_submission/server.py", line 247, in <module>
    main()
  File "/w/home.27/ee/ugrad/jiayun/CS131/Project/./sample_submission/server.py", line 242, in main
    asyncio.run(server.run_forever())
  File "/usr/local/cs/Python-3.9.0/lib/python3.9/asyncio/runners.py", line 44, in run
    return loop.run_until_complete(main)
  File "/usr/local/cs/Python-3.9.0/lib/python3.9/asyncio/base_events.py", line 642, in run_until_complete
    return future.result()
  File "/w/home.27/ee/ugrad/jiayun/CS131/Project/./sample_submission/server.py", line 191, in run_forever
    server = await asyncio.start_server(self.handle_input, self.ip, self.port)
  File "/usr/local/cs/Python-3.9.0/lib/python3.9/asyncio/streams.py", line 94, in start_server
    return await loop.create_server(factory, host, port, **kwds)
  File "/usr/local/cs/Python-3.9.0/lib/python3.9/asyncio/base_events.py", line 1494, in create_server
    raise OSError(err.errno, 'error while attempting '
OSError: [Errno 98] error while attempting to bind on address ('127.0.0.1', 12442): address already in use
Traceback (most recent call last):
  File "/w/home.27/ee/ugrad/jiayun/CS131/Project/./sample_submission/server.py", line 247, in <module>
    main()
  File "/w/home.27/ee/ugrad/jiayun/CS131/Project/./sample_submission/server.py", line 242, in main
    asyncio.run(server.run_forever())
  File "/usr/local/cs/Python-3.9.0/lib/python3.9/asyncio/runners.py", line 44, in run
    return loop.run_until_complete(main)
  File "/usr/local/cs/Python-3.9.0/lib/python3.9/asyncio/base_events.py", line 642, in run_until_complete
    return future.result()
  File "/w/home.27/ee/ugrad/jiayun/CS131/Project/./sample_submission/server.py", line 191, in run_forever
    server = await asyncio.start_server(self.handle_input, self.ip, self.port)
  File "/usr/local/cs/Python-3.9.0/lib/python3.9/asyncio/streams.py", line 94, in start_server
    return await loop.create_server(factory, host, port, **kwds)
  File "/usr/local/cs/Python-3.9.0/lib/python3.9/asyncio/base_events.py", line 1494, in create_server
    raise OSError(err.errno, 'error while attempting '
OSError: [Errno 98] error while attempting to bind on address ('127.0.0.1', 12444): address already in use
Traceback (most recent call last):
  File "/w/home.27/ee/ugrad/jiayun/CS131/Project/./sample_submission/server.py", line 247, in <module>
    main()
  File "/w/home.27/ee/ugrad/jiayun/CS131/Project/./sample_submission/server.py", line 242, in main
    asyncio.run(server.run_forever())
  File "/usr/local/cs/Python-3.9.0/lib/python3.9/asyncio/runners.py", line 44, in run
    return loop.run_until_complete(main)
  File "/usr/local/cs/Python-3.9.0/lib/python3.9/asyncio/base_events.py", line 642, in run_until_complete
    return future.result()
  File "/w/home.27/ee/ugrad/jiayun/CS131/Project/./sample_submission/server.py", line 191, in run_forever
    server = await asyncio.start_server(self.handle_input, self.ip, self.port)
  File "/usr/local/cs/Python-3.9.0/lib/python3.9/asyncio/streams.py", line 94, in start_server
    return await loop.create_server(factory, host, port, **kwds)
  File "/usr/local/cs/Python-3.9.0/lib/python3.9/asyncio/base_events.py", line 1494, in create_server
    raise OSError(err.errno, 'error while attempting '
OSError: [Errno 98] error while attempting to bind on address ('127.0.0.1', 12443): address already in use
Traceback (most recent call last):
  File "/w/home.27/ee/ugrad/jiayun/CS131/Project/./sample_submission/server.py", line 247, in <module>
    main()
  File "/w/home.27/ee/ugrad/jiayun/CS131/Project/./sample_submission/server.py", line 242, in main
    asyncio.run(server.run_forever())
  File "/usr/local/cs/Python-3.9.0/lib/python3.9/asyncio/runners.py", line 44, in run
    return loop.run_until_complete(main)
  File "/usr/local/cs/Python-3.9.0/lib/python3.9/asyncio/base_events.py", line 642, in run_until_complete
    return future.result()
  File "/w/home.27/ee/ugrad/jiayun/CS131/Project/./sample_submission/server.py", line 191, in run_forever
    server = await asyncio.start_server(self.handle_input, self.ip, self.port)
  File "/usr/local/cs/Python-3.9.0/lib/python3.9/asyncio/streams.py", line 94, in start_server
    return await loop.create_server(factory, host, port, **kwds)
  File "/usr/local/cs/Python-3.9.0/lib/python3.9/asyncio/base_events.py", line 1494, in create_server
    raise OSError(err.errno, 'error while attempting '
OSError: [Errno 98] error while attempting to bind on address ('127.0.0.1', 12440): address already in use
Traceback (most recent call last):
  File "/w/home.27/ee/ugrad/jiayun/CS131/Project/./sample_submission/server.py", line 247, in <module>
    main()
  File "/w/home.27/ee/ugrad/jiayun/CS131/Project/./sample_submission/server.py", line 242, in main
    asyncio.run(server.run_forever())
  File "/usr/local/cs/Python-3.9.0/lib/python3.9/asyncio/runners.py", line 44, in run
    return loop.run_until_complete(main)
  File "/usr/local/cs/Python-3.9.0/lib/python3.9/asyncio/base_events.py", line 642, in run_until_complete
    return future.result()
  File "/w/home.27/ee/ugrad/jiayun/CS131/Project/./sample_submission/server.py", line 191, in run_forever
    server = await asyncio.start_server(self.handle_input, self.ip, self.port)
  File "/usr/local/cs/Python-3.9.0/lib/python3.9/asyncio/streams.py", line 94, in start_server
    return await loop.create_server(factory, host, port, **kwds)
  File "/usr/local/cs/Python-3.9.0/lib/python3.9/asyncio/base_events.py", line 1494, in create_server
    raise OSError(err.errno, 'error while attempting '
OSError: [Errno 98] error while attempting to bind on address ('127.0.0.1', 12441): address already in use
Traceback (most recent call last):
  File "/w/home.27/ee/ugrad/jiayun/CS131/Project/./sample_submission/server.py", line 247, in <module>
    main()
  File "/w/home.27/ee/ugrad/jiayun/CS131/Project/./sample_submission/server.py", line 242, in main
    asyncio.run(server.run_forever())
  File "/usr/local/cs/Python-3.9.0/lib/python3.9/asyncio/runners.py", line 44, in run
    return loop.run_until_complete(main)
  File "/usr/local/cs/Python-3.9.0/lib/python3.9/asyncio/base_events.py", line 642, in run_until_complete
    return future.result()
  File "/w/home.27/ee/ugrad/jiayun/CS131/Project/./sample_submission/server.py", line 191, in run_forever
    server = await asyncio.start_server(self.handle_input, self.ip, self.port)
  File "/usr/local/cs/Python-3.9.0/lib/python3.9/asyncio/streams.py", line 94, in start_server
    return await loop.create_server(factory, host, port, **kwds)
  File "/usr/local/cs/Python-3.9.0/lib/python3.9/asyncio/base_events.py", line 1494, in create_server
    raise OSError(err.errno, 'error while attempting '
OSError: [Errno 98] error while attempting to bind on address ('127.0.0.1', 12442): address already in use
Traceback (most recent call last):
  File "/w/home.27/ee/ugrad/jiayun/CS131/Project/./sample_submission/server.py", line 247, in <module>
    main()
  File "/w/home.27/ee/ugrad/jiayun/CS131/Project/./sample_submission/server.py", line 242, in main
    asyncio.run(server.run_forever())
  File "/usr/local/cs/Python-3.9.0/lib/python3.9/asyncio/runners.py", line 44, in run
    return loop.run_until_complete(main)
  File "/usr/local/cs/Python-3.9.0/lib/python3.9/asyncio/base_events.py", line 642, in run_until_complete
    return future.result()
  File "/w/home.27/ee/ugrad/jiayun/CS131/Project/./sample_submission/server.py", line 191, in run_forever
    server = await asyncio.start_server(self.handle_input, self.ip, self.port)
  File "/usr/local/cs/Python-3.9.0/lib/python3.9/asyncio/streams.py", line 94, in start_server
    return await loop.create_server(factory, host, port, **kwds)
  File "/usr/local/cs/Python-3.9.0/lib/python3.9/asyncio/base_events.py", line 1494, in create_server
    raise OSError(err.errno, 'error while attempting '
OSError: [Errno 98] error while attempting to bind on address ('127.0.0.1', 12443): address already in use
Traceback (most recent call last):
  File "/w/home.27/ee/ugrad/jiayun/CS131/Project/./sample_submission/server.py", line 247, in <module>
    main()
  File "/w/home.27/ee/ugrad/jiayun/CS131/Project/./sample_submission/server.py", line 242, in main
    asyncio.run(server.run_forever())
  File "/usr/local/cs/Python-3.9.0/lib/python3.9/asyncio/runners.py", line 44, in run
    return loop.run_until_complete(main)
  File "/usr/local/cs/Python-3.9.0/lib/python3.9/asyncio/base_events.py", line 642, in run_until_complete
    return future.result()
  File "/w/home.27/ee/ugrad/jiayun/CS131/Project/./sample_submission/server.py", line 191, in run_forever
    server = await asyncio.start_server(self.handle_input, self.ip, self.port)
  File "/usr/local/cs/Python-3.9.0/lib/python3.9/asyncio/streams.py", line 94, in start_server
    return await loop.create_server(factory, host, port, **kwds)
  File "/usr/local/cs/Python-3.9.0/lib/python3.9/asyncio/base_events.py", line 1494, in create_server
    raise OSError(err.errno, 'error while attempting '
OSError: [Errno 98] error while attempting to bind on address ('127.0.0.1', 12444): address already in use
Traceback (most recent call last):
  File "/w/home.27/ee/ugrad/jiayun/CS131/Project/./sample_submission/server.py", line 247, in <module>
    main()
  File "/w/home.27/ee/ugrad/jiayun/CS131/Project/./sample_submission/server.py", line 242, in main
    asyncio.run(server.run_forever())
  File "/usr/local/cs/Python-3.9.0/lib/python3.9/asyncio/runners.py", line 44, in run
    return loop.run_until_complete(main)
  File "/usr/local/cs/Python-3.9.0/lib/python3.9/asyncio/base_events.py", line 642, in run_until_complete
    return future.result()
  File "/w/home.27/ee/ugrad/jiayun/CS131/Project/./sample_submission/server.py", line 191, in run_forever
    server = await asyncio.start_server(self.handle_input, self.ip, self.port)
  File "/usr/local/cs/Python-3.9.0/lib/python3.9/asyncio/streams.py", line 94, in start_server
    return await loop.create_server(factory, host, port, **kwds)
  File "/usr/local/cs/Python-3.9.0/lib/python3.9/asyncio/base_events.py", line 1494, in create_server
    raise OSError(err.errno, 'error while attempting '
OSError: [Errno 98] error while attempting to bind on address ('127.0.0.1', 12441): address already in use
Traceback (most recent call last):
  File "/w/home.27/ee/ugrad/jiayun/CS131/Project/./sample_submission/server.py", line 247, in <module>
    main()
  File "/w/home.27/ee/ugrad/jiayun/CS131/Project/./sample_submission/server.py", line 242, in main
    asyncio.run(server.run_forever())
  File "/usr/local/cs/Python-3.9.0/lib/python3.9/asyncio/runners.py", line 44, in run
    return loop.run_until_complete(main)
  File "/usr/local/cs/Python-3.9.0/lib/python3.9/asyncio/base_events.py", line 642, in run_until_complete
    return future.result()
  File "/w/home.27/ee/ugrad/jiayun/CS131/Project/./sample_submission/server.py", line 191, in run_forever
    server = await asyncio.start_server(self.handle_input, self.ip, self.port)
  File "/usr/local/cs/Python-3.9.0/lib/python3.9/asyncio/streams.py", line 94, in start_server
    return await loop.create_server(factory, host, port, **kwds)
  File "/usr/local/cs/Python-3.9.0/lib/python3.9/asyncio/base_events.py", line 1494, in create_server
    raise OSError(err.errno, 'error while attempting '
OSError: [Errno 98] error while attempting to bind on address ('127.0.0.1', 12442): address already in use
Traceback (most recent call last):
  File "/w/home.27/ee/ugrad/jiayun/CS131/Project/./sample_submission/server.py", line 247, in <module>
    main()
  File "/w/home.27/ee/ugrad/jiayun/CS131/Project/./sample_submission/server.py", line 242, in main
    asyncio.run(server.run_forever())
  File "/usr/local/cs/Python-3.9.0/lib/python3.9/asyncio/runners.py", line 44, in run
    return loop.run_until_complete(main)
  File "/usr/local/cs/Python-3.9.0/lib/python3.9/asyncio/base_events.py", line 642, in run_until_complete
    return future.result()
  File "/w/home.27/ee/ugrad/jiayun/CS131/Project/./sample_submission/server.py", line 191, in run_forever
    server = await asyncio.start_server(self.handle_input, self.ip, self.port)
  File "/usr/local/cs/Python-3.9.0/lib/python3.9/asyncio/streams.py", line 94, in start_server
    return await loop.create_server(factory, host, port, **kwds)
  File "/usr/local/cs/Python-3.9.0/lib/python3.9/asyncio/base_events.py", line 1494, in create_server
    raise OSError(err.errno, 'error while attempting '
OSError: [Errno 98] error while attempting to bind on address ('127.0.0.1', 12443): address already in use
Traceback (most recent call last):
  File "/w/home.27/ee/ugrad/jiayun/CS131/Project/./sample_submission/server.py", line 247, in <module>
    main()
  File "/w/home.27/ee/ugrad/jiayun/CS131/Project/./sample_submission/server.py", line 242, in main
    asyncio.run(server.run_forever())
  File "/usr/local/cs/Python-3.9.0/lib/python3.9/asyncio/runners.py", line 44, in run
    return loop.run_until_complete(main)
  File "/usr/local/cs/Python-3.9.0/lib/python3.9/asyncio/base_events.py", line 642, in run_until_complete
    return future.result()
  File "/w/home.27/ee/ugrad/jiayun/CS131/Project/./sample_submission/server.py", line 191, in run_forever
    server = await asyncio.start_server(self.handle_input, self.ip, self.port)
  File "/usr/local/cs/Python-3.9.0/lib/python3.9/asyncio/streams.py", line 94, in start_server
    return await loop.create_server(factory, host, port, **kwds)
  File "/usr/local/cs/Python-3.9.0/lib/python3.9/asyncio/base_events.py", line 1494, in create_server
    raise OSError(err.errno, 'error while attempting '
OSError: [Errno 98] error while attempting to bind on address ('127.0.0.1', 12444): address already in use
Traceback (most recent call last):
  File "/w/home.27/ee/ugrad/jiayun/CS131/Project/./sample_submission/server.py", line 247, in <module>
    main()
  File "/w/home.27/ee/ugrad/jiayun/CS131/Project/./sample_submission/server.py", line 242, in main
    asyncio.run(server.run_forever())
  File "/usr/local/cs/Python-3.9.0/lib/python3.9/asyncio/runners.py", line 44, in run
    return loop.run_until_complete(main)
  File "/usr/local/cs/Python-3.9.0/lib/python3.9/asyncio/base_events.py", line 642, in run_until_complete
    return future.result()
  File "/w/home.27/ee/ugrad/jiayun/CS131/Project/./sample_submission/server.py", line 191, in run_forever
    server = await asyncio.start_server(self.handle_input, self.ip, self.port)
  File "/usr/local/cs/Python-3.9.0/lib/python3.9/asyncio/streams.py", line 94, in start_server
    return await loop.create_server(factory, host, port, **kwds)
  File "/usr/local/cs/Python-3.9.0/lib/python3.9/asyncio/base_events.py", line 1494, in create_server
    raise OSError(err.errno, 'error while attempting '
OSError: [Errno 98] error while attempting to bind on address ('127.0.0.1', 12440): address already in use
Traceback (most recent call last):
  File "/w/home.27/ee/ugrad/jiayun/CS131/Project/./sample_submission/server.py", line 247, in <module>
    main()
  File "/w/home.27/ee/ugrad/jiayun/CS131/Project/./sample_submission/server.py", line 242, in main
    asyncio.run(server.run_forever())
  File "/usr/local/cs/Python-3.9.0/lib/python3.9/asyncio/runners.py", line 44, in run
    return loop.run_until_complete(main)
  File "/usr/local/cs/Python-3.9.0/lib/python3.9/asyncio/base_events.py", line 642, in run_until_complete
    return future.result()
  File "/w/home.27/ee/ugrad/jiayun/CS131/Project/./sample_submission/server.py", line 191, in run_forever
    server = await asyncio.start_server(self.handle_input, self.ip, self.port)
  File "/usr/local/cs/Python-3.9.0/lib/python3.9/asyncio/streams.py", line 94, in start_server
    return await loop.create_server(factory, host, port, **kwds)
  File "/usr/local/cs/Python-3.9.0/lib/python3.9/asyncio/base_events.py", line 1494, in create_server
    raise OSError(err.errno, 'error while attempting '
OSError: [Errno 98] error while attempting to bind on address ('127.0.0.1', 12442): address already in use
Traceback (most recent call last):
  File "/w/home.27/ee/ugrad/jiayun/CS131/Project/./sample_submission/server.py", line 247, in <module>
    main()
  File "/w/home.27/ee/ugrad/jiayun/CS131/Project/./sample_submission/server.py", line 242, in main
    asyncio.run(server.run_forever())
  File "/usr/local/cs/Python-3.9.0/lib/python3.9/asyncio/runners.py", line 44, in run
    return loop.run_until_complete(main)
  File "/usr/local/cs/Python-3.9.0/lib/python3.9/asyncio/base_events.py", line 642, in run_until_complete
    return future.result()
  File "/w/home.27/ee/ugrad/jiayun/CS131/Project/./sample_submission/server.py", line 191, in run_forever
    server = await asyncio.start_server(self.handle_input, self.ip, self.port)
  File "/usr/local/cs/Python-3.9.0/lib/python3.9/asyncio/streams.py", line 94, in start_server
    return await loop.create_server(factory, host, port, **kwds)
  File "/usr/local/cs/Python-3.9.0/lib/python3.9/asyncio/base_events.py", line 1494, in create_server
    raise OSError(err.errno, 'error while attempting '
OSError: [Errno 98] error while attempting to bind on address ('127.0.0.1', 12443): address already in use
Traceback (most recent call last):
  File "/w/home.27/ee/ugrad/jiayun/CS131/Project/./sample_submission/server.py", line 247, in <module>
    main()
  File "/w/home.27/ee/ugrad/jiayun/CS131/Project/./sample_submission/server.py", line 242, in main
    asyncio.run(server.run_forever())
  File "/usr/local/cs/Python-3.9.0/lib/python3.9/asyncio/runners.py", line 44, in run
    return loop.run_until_complete(main)
  File "/usr/local/cs/Python-3.9.0/lib/python3.9/asyncio/base_events.py", line 642, in run_until_complete
    return future.result()
  File "/w/home.27/ee/ugrad/jiayun/CS131/Project/./sample_submission/server.py", line 191, in run_forever
    server = await asyncio.start_server(self.handle_input, self.ip, self.port)
  File "/usr/local/cs/Python-3.9.0/lib/python3.9/asyncio/streams.py", line 94, in start_server
    return await loop.create_server(factory, host, port, **kwds)
  File "/usr/local/cs/Python-3.9.0/lib/python3.9/asyncio/base_events.py", line 1494, in create_server
    raise OSError(err.errno, 'error while attempting '
OSError: [Errno 98] error while attempting to bind on address ('127.0.0.1', 12444): address already in use
Traceback (most recent call last):
  File "/w/home.27/ee/ugrad/jiayun/CS131/Project/./sample_submission/server.py", line 247, in <module>
    main()
  File "/w/home.27/ee/ugrad/jiayun/CS131/Project/./sample_submission/server.py", line 242, in main
    asyncio.run(server.run_forever())
  File "/usr/local/cs/Python-3.9.0/lib/python3.9/asyncio/runners.py", line 44, in run
    return loop.run_until_complete(main)
  File "/usr/local/cs/Python-3.9.0/lib/python3.9/asyncio/base_events.py", line 642, in run_until_complete
    return future.result()
  File "/w/home.27/ee/ugrad/jiayun/CS131/Project/./sample_submission/server.py", line 191, in run_forever
    server = await asyncio.start_server(self.handle_input, self.ip, self.port)
  File "/usr/local/cs/Python-3.9.0/lib/python3.9/asyncio/streams.py", line 94, in start_server
    return await loop.create_server(factory, host, port, **kwds)
  File "/usr/local/cs/Python-3.9.0/lib/python3.9/asyncio/base_events.py", line 1494, in create_server
    raise OSError(err.errno, 'error while attempting '
OSError: [Errno 98] error while attempting to bind on address ('127.0.0.1', 12441): address already in use
Traceback (most recent call last):
  File "/w/home.27/ee/ugrad/jiayun/CS131/Project/./sample_submission/server.py", line 247, in <module>
    main()
  File "/w/home.27/ee/ugrad/jiayun/CS131/Project/./sample_submission/server.py", line 242, in main
    asyncio.run(server.run_forever())
  File "/usr/local/cs/Python-3.9.0/lib/python3.9/asyncio/runners.py", line 44, in run
    return loop.run_until_complete(main)
  File "/usr/local/cs/Python-3.9.0/lib/python3.9/asyncio/base_events.py", line 642, in run_until_complete
    return future.result()
  File "/w/home.27/ee/ugrad/jiayun/CS131/Project/./sample_submission/server.py", line 191, in run_forever
    server = await asyncio.start_server(self.handle_input, self.ip, self.port)
  File "/usr/local/cs/Python-3.9.0/lib/python3.9/asyncio/streams.py", line 94, in start_server
    return await loop.create_server(factory, host, port, **kwds)
  File "/usr/local/cs/Python-3.9.0/lib/python3.9/asyncio/base_events.py", line 1494, in create_server
    raise OSError(err.errno, 'error while attempting '
OSError: [Errno 98] error while attempting to bind on address ('127.0.0.1', 12443): address already in use
Traceback (most recent call last):
  File "/w/home.27/ee/ugrad/jiayun/CS131/Project/./sample_submission/server.py", line 247, in <module>
    main()
  File "/w/home.27/ee/ugrad/jiayun/CS131/Project/./sample_submission/server.py", line 242, in main
    asyncio.run(server.run_forever())
  File "/usr/local/cs/Python-3.9.0/lib/python3.9/asyncio/runners.py", line 44, in run
    return loop.run_until_complete(main)
  File "/usr/local/cs/Python-3.9.0/lib/python3.9/asyncio/base_events.py", line 642, in run_until_complete
    return future.result()
  File "/w/home.27/ee/ugrad/jiayun/CS131/Project/./sample_submission/server.py", line 191, in run_forever
    server = await asyncio.start_server(self.handle_input, self.ip, self.port)
  File "/usr/local/cs/Python-3.9.0/lib/python3.9/asyncio/streams.py", line 94, in start_server
    return await loop.create_server(factory, host, port, **kwds)
  File "/usr/local/cs/Python-3.9.0/lib/python3.9/asyncio/base_events.py", line 1494, in create_server
    raise OSError(err.errno, 'error while attempting '
OSError: [Errno 98] error while attempting to bind on address ('127.0.0.1', 12444): address already in use
Traceback (most recent call last):
  File "/w/home.27/ee/ugrad/jiayun/CS131/Project/./sample_submission/server.py", line 247, in <module>
    main()
  File "/w/home.27/ee/ugrad/jiayun/CS131/Project/./sample_submission/server.py", line 242, in main
    asyncio.run(server.run_forever())
  File "/usr/local/cs/Python-3.9.0/lib/python3.9/asyncio/runners.py", line 44, in run
    return loop.run_until_complete(main)
  File "/usr/local/cs/Python-3.9.0/lib/python3.9/asyncio/base_events.py", line 642, in run_until_complete
    return future.result()
  File "/w/home.27/ee/ugrad/jiayun/CS131/Project/./sample_submission/server.py", line 191, in run_forever
    server = await asyncio.start_server(self.handle_input, self.ip, self.port)
  File "/usr/local/cs/Python-3.9.0/lib/python3.9/asyncio/streams.py", line 94, in start_server
    return await loop.create_server(factory, host, port, **kwds)
  File "/usr/local/cs/Python-3.9.0/lib/python3.9/asyncio/base_events.py", line 1494, in create_server
    raise OSError(err.errno, 'error while attempting '
OSError: [Errno 98] error while attempting to bind on address ('127.0.0.1', 12442): address already in use
Traceback (most recent call last):
  File "/w/home.27/ee/ugrad/jiayun/CS131/Project/./sample_submission/server.py", line 247, in <module>
    main()
  File "/w/home.27/ee/ugrad/jiayun/CS131/Project/./sample_submission/server.py", line 242, in main
    asyncio.run(server.run_forever())
  File "/usr/local/cs/Python-3.9.0/lib/python3.9/asyncio/runners.py", line 44, in run
    return loop.run_until_complete(main)
  File "/usr/local/cs/Python-3.9.0/lib/python3.9/asyncio/base_events.py", line 642, in run_until_complete
    return future.result()
  File "/w/home.27/ee/ugrad/jiayun/CS131/Project/./sample_submission/server.py", line 191, in run_forever
    server = await asyncio.start_server(self.handle_input, self.ip, self.port)
  File "/usr/local/cs/Python-3.9.0/lib/python3.9/asyncio/streams.py", line 94, in start_server
    return await loop.create_server(factory, host, port, **kwds)
  File "/usr/local/cs/Python-3.9.0/lib/python3.9/asyncio/base_events.py", line 1494, in create_server
    raise OSError(err.errno, 'error while attempting '
OSError: [Errno 98] error while attempting to bind on address ('127.0.0.1', 12444): address already in use
Traceback (most recent call last):
  File "/w/home.27/ee/ugrad/jiayun/CS131/Project/./sample_submission/server.py", line 247, in <module>
    main()
  File "/w/home.27/ee/ugrad/jiayun/CS131/Project/./sample_submission/server.py", line 242, in main
    asyncio.run(server.run_forever())
  File "/usr/local/cs/Python-3.9.0/lib/python3.9/asyncio/runners.py", line 44, in run
    return loop.run_until_complete(main)
  File "/usr/local/cs/Python-3.9.0/lib/python3.9/asyncio/base_events.py", line 642, in run_until_complete
    return future.result()
  File "/w/home.27/ee/ugrad/jiayun/CS131/Project/./sample_submission/server.py", line 191, in run_forever
    server = await asyncio.start_server(self.handle_input, self.ip, self.port)
  File "/usr/local/cs/Python-3.9.0/lib/python3.9/asyncio/streams.py", line 94, in start_server
    return await loop.create_server(factory, host, port, **kwds)
  File "/usr/local/cs/Python-3.9.0/lib/python3.9/asyncio/base_events.py", line 1494, in create_server
    raise OSError(err.errno, 'error while attempting '
OSError: [Errno 98] error while attempting to bind on address ('127.0.0.1', 12443): address already in use
  File "/w/home.27/ee/ugrad/jiayun/CS131/Project/./sample_submission/server.py", line 17
    "Smith", 12442,
           ^
SyntaxError: invalid syntax
  File "/w/home.27/ee/ugrad/jiayun/CS131/Project/./sample_submission/server.py", line 17
    "Smith", 12442,
           ^
SyntaxError: invalid syntax
  File "/w/home.27/ee/ugrad/jiayun/CS131/Project/./sample_submission/server.py", line 17
    "Smith", 12442,
           ^
SyntaxError: invalid syntax
  File "/w/home.27/ee/ugrad/jiayun/CS131/Project/./sample_submission/server.py", line 17
    "Smith", 12442,
           ^
SyntaxError: invalid syntax
  File "/w/home.27/ee/ugrad/jiayun/CS131/Project/./sample_submission/server.py", line 17
    "Smith", 12442,
           ^
SyntaxError: invalid syntax
  File "/w/home.27/ee/ugrad/jiayun/CS131/Project/./sample_submission/server.py", line 17
    "Smith", 12442,
           ^
SyntaxError: invalid syntax
  File "/w/home.27/ee/ugrad/jiayun/CS131/Project/./sample_submission/server.py", line 17
    "Smith", 12442,
           ^
SyntaxError: invalid syntax
  File "/w/home.27/ee/ugrad/jiayun/CS131/Project/./sample_submission/server.py", line 17
    "Smith", 12442,
           ^
SyntaxError: invalid syntax
  File "/w/home.27/ee/ugrad/jiayun/CS131/Project/./sample_submission/server.py", line 17
    "Smith", 12442,
           ^
SyntaxError: invalid syntax
  File "/w/home.27/ee/ugrad/jiayun/CS131/Project/./sample_submission/server.py", line 17
    "Smith", 12442,
           ^
SyntaxError: invalid syntax
  File "/w/home.27/ee/ugrad/jiayun/CS131/Project/./sample_submission/server.py", line 17
    "Smith", 12442,
           ^
SyntaxError: invalid syntax
  File "/w/home.27/ee/ugrad/jiayun/CS131/Project/./sample_submission/server.py", line 17
    "Smith", 12442,
           ^
SyntaxError: invalid syntax
  File "/w/home.27/ee/ugrad/jiayun/CS131/Project/./sample_submission/server.py", line 17
    "Smith", 12442,
           ^
SyntaxError: invalid syntax
  File "/w/home.27/ee/ugrad/jiayun/CS131/Project/./sample_submission/server.py", line 17
    "Smith", 12442,
           ^
SyntaxError: invalid syntax
  File "/w/home.27/ee/ugrad/jiayun/CS131/Project/./sample_submission/server.py", line 17
    "Smith", 12442,
           ^
SyntaxError: invalid syntax
  File "/w/home.27/ee/ugrad/jiayun/CS131/Project/./sample_submission/server.py", line 17
    "Smith", 12442,
           ^
SyntaxError: invalid syntax
  File "/w/home.27/ee/ugrad/jiayun/CS131/Project/./sample_submission/server.py", line 17
    "Smith", 12442,
           ^
SyntaxError: invalid syntax
  File "/w/home.27/ee/ugrad/jiayun/CS131/Project/./sample_submission/server.py", line 17
    "Smith", 12442,
           ^
SyntaxError: invalid syntax
  File "/w/home.27/ee/ugrad/jiayun/CS131/Project/./sample_submission/server.py", line 17
    "Smith", 12442,
           ^
SyntaxError: invalid syntax
  File "/w/home.27/ee/ugrad/jiayun/CS131/Project/./sample_submission/server.py", line 17
    "Smith", 12442,
           ^
SyntaxError: invalid syntax
  File "/w/home.27/ee/ugrad/jiayun/CS131/Project/./sample_submission/server.py", line 17
    "Smith", 12442,
           ^
SyntaxError: invalid syntax
  File "/w/home.27/ee/ugrad/jiayun/CS131/Project/./sample_submission/server.py", line 17
    "Smith", 12442,
           ^
SyntaxError: invalid syntax
  File "/w/home.27/ee/ugrad/jiayun/CS131/Project/./sample_submission/server.py", line 17
    "Smith", 12442,
           ^
SyntaxError: invalid syntax
  File "/w/home.27/ee/ugrad/jiayun/CS131/Project/./sample_submission/server.py", line 17
    "Smith", 12442,
           ^
SyntaxError: invalid syntax
  File "/w/home.27/ee/ugrad/jiayun/CS131/Project/./sample_submission/server.py", line 17
    "Smith", 12442,
           ^
SyntaxError: invalid syntax
  File "/w/home.27/ee/ugrad/jiayun/CS131/Project/./sample_submission/server.py", line 17
    "Smith", 12442,
           ^
SyntaxError: invalid syntax
  File "/w/home.27/ee/ugrad/jiayun/CS131/Project/./sample_submission/server.py", line 17
    "Smith", 12442,
           ^
SyntaxError: invalid syntax
  File "/w/home.27/ee/ugrad/jiayun/CS131/Project/./sample_submission/server.py", line 17
    "Smith", 12442,
           ^
SyntaxError: invalid syntax
  File "/w/home.27/ee/ugrad/jiayun/CS131/Project/./sample_submission/server.py", line 17
    "Smith", 12442,
           ^
SyntaxError: invalid syntax
  File "/w/home.27/ee/ugrad/jiayun/CS131/Project/./sample_submission/server.py", line 17
    "Smith", 12442,
           ^
SyntaxError: invalid syntax
  File "/w/home.27/ee/ugrad/jiayun/CS131/Project/./sample_submission/server.py", line 17
    "Smith", 12442,
           ^
SyntaxError: invalid syntax
  File "/w/home.27/ee/ugrad/jiayun/CS131/Project/./sample_submission/server.py", line 17
    "Smith", 12442,
           ^
SyntaxError: invalid syntax
  File "/w/home.27/ee/ugrad/jiayun/CS131/Project/./sample_submission/server.py", line 17
    "Smith", 12442,
           ^
SyntaxError: invalid syntax
  File "/w/home.27/ee/ugrad/jiayun/CS131/Project/./sample_submission/server.py", line 17
    "Smith", 12442,
           ^
SyntaxError: invalid syntax
  File "/w/home.27/ee/ugrad/jiayun/CS131/Project/./sample_submission/server.py", line 17
    "Smith", 12442,
           ^
SyntaxError: invalid syntax
  File "/w/home.27/ee/ugrad/jiayun/CS131/Project/./sample_submission/server.py", line 17
    "Smith", 12442,
           ^
SyntaxError: invalid syntax
  File "/w/home.27/ee/ugrad/jiayun/CS131/Project/./sample_submission/server.py", line 17
    "Smith", 12442,
           ^
SyntaxError: invalid syntax
  File "/w/home.27/ee/ugrad/jiayun/CS131/Project/./sample_submission/server.py", line 17
    "Smith", 12442,
           ^
SyntaxError: invalid syntax
  File "/w/home.27/ee/ugrad/jiayun/CS131/Project/./sample_submission/server.py", line 17
    "Smith", 12442,
           ^
SyntaxError: invalid syntax
  File "/w/home.27/ee/ugrad/jiayun/CS131/Project/./sample_submission/server.py", line 17
    "Smith", 12442,
           ^
SyntaxError: invalid syntax
  File "/w/home.27/ee/ugrad/jiayun/CS131/Project/./sample_submission/server.py", line 17
    "Smith", 12442,
           ^
SyntaxError: invalid syntax
  File "/w/home.27/ee/ugrad/jiayun/CS131/Project/./sample_submission/server.py", line 17
    "Smith", 12442,
           ^
SyntaxError: invalid syntax
  File "/w/home.27/ee/ugrad/jiayun/CS131/Project/./sample_submission/server.py", line 17
    "Smith", 12442,
           ^
SyntaxError: invalid syntax
  File "/w/home.27/ee/ugrad/jiayun/CS131/Project/./sample_submission/server.py", line 17
    "Smith", 12442,
           ^
SyntaxError: invalid syntax
  File "/w/home.27/ee/ugrad/jiayun/CS131/Project/./sample_submission/server.py", line 17
    "Smith", 12442,
           ^
SyntaxError: invalid syntax
  File "/w/home.27/ee/ugrad/jiayun/CS131/Project/./sample_submission/server.py", line 17
    "Smith", 12442,
           ^
SyntaxError: invalid syntax
  File "/w/home.27/ee/ugrad/jiayun/CS131/Project/./sample_submission/server.py", line 17
    "Smith", 12442,
           ^
SyntaxError: invalid syntax
  File "/w/home.27/ee/ugrad/jiayun/CS131/Project/./sample_submission/server.py", line 17
    "Smith", 12442,
           ^
SyntaxError: invalid syntax
  File "/w/home.27/ee/ugrad/jiayun/CS131/Project/./sample_submission/server.py", line 17
    "Smith", 12442,
           ^
SyntaxError: invalid syntax
  File "/w/home.27/ee/ugrad/jiayun/CS131/Project/./sample_submission/server.py", line 17
    "Smith", 12442,
           ^
SyntaxError: invalid syntax
  File "/w/home.27/ee/ugrad/jiayun/CS131/Project/./sample_submission/server.py", line 17
    "Smith", 12442,
           ^
SyntaxError: invalid syntax
  File "/w/home.27/ee/ugrad/jiayun/CS131/Project/./sample_submission/server.py", line 17
    "Smith", 12442,
           ^
SyntaxError: invalid syntax
  File "/w/home.27/ee/ugrad/jiayun/CS131/Project/./sample_submission/server.py", line 17
    "Smith", 12442,
           ^
SyntaxError: invalid syntax
  File "/w/home.27/ee/ugrad/jiayun/CS131/Project/./sample_submission/server.py", line 17
    "Smith", 12442,
           ^
SyntaxError: invalid syntax
  File "/w/home.27/ee/ugrad/jiayun/CS131/Project/./sample_submission/server.py", line 17
    "Smith", 12442,
           ^
SyntaxError: invalid syntax
  File "/w/home.27/ee/ugrad/jiayun/CS131/Project/./sample_submission/server.py", line 17
    "Smith", 12442,
           ^
SyntaxError: invalid syntax
  File "/w/home.27/ee/ugrad/jiayun/CS131/Project/./sample_submission/server.py", line 17
    "Smith", 12442,
           ^
SyntaxError: invalid syntax
                                                                                                                                                                                                                                                                                                                                                                                                                                                                                                                                                                                                                                                                                                                                                                                                                                                                                                                                                                                                                                                                                                                                                                                                                                                                                                                                                                                                                                                                                                                                                              File "/w/home.27/ee/ugrad/jiayun/CS131/Project/./sample_submission/server.py", line 17
    "Smith", 12442,
           ^
SyntaxError: invalid syntax
  File "/w/home.27/ee/ugrad/jiayun/CS131/Project/./sample_submission/server.py", line 17
    "Smith", 12442,
           ^
SyntaxError: invalid syntax
  File "/w/home.27/ee/ugrad/jiayun/CS131/Project/./sample_submission/server.py", line 17
    "Smith", 12442,
           ^
SyntaxError: invalid syntax
  File "/w/home.27/ee/ugrad/jiayun/CS131/Project/./sample_submission/server.py", line 17
    "Smith", 12442,
           ^
SyntaxError: invalid syntax
  File "/w/home.27/ee/ugrad/jiayun/CS131/Project/./sample_submission/server.py", line 17
    "Smith", 12442,
           ^
SyntaxError: invalid syntax
  File "/w/home.27/ee/ugrad/jiayun/CS131/Project/./sample_submission/server.py", line 17
    "Smith", 12442,
           ^
SyntaxError: invalid syntax
  File "/w/home.27/ee/ugrad/jiayun/CS131/Project/./sample_submission/server.py", line 17
    "Smith", 12442,
           ^
SyntaxError: invalid syntax
  File "/w/home.27/ee/ugrad/jiayun/CS131/Project/./sample_submission/server.py", line 17
    "Smith", 12442,
           ^
SyntaxError: invalid syntax
  File "/w/home.27/ee/ugrad/jiayun/CS131/Project/./sample_submission/server.py", line 17
    "Smith", 12442,
           ^
SyntaxError: invalid syntax
  File "/w/home.27/ee/ugrad/jiayun/CS131/Project/./sample_submission/server.py", line 17
    "Smith", 12442,
           ^
SyntaxError: invalid syntax
  File "/w/home.27/ee/ugrad/jiayun/CS131/Project/./sample_submission/server.py", line 17
    "Smith", 12442,
           ^
SyntaxError: invalid syntax
  File "/w/home.27/ee/ugrad/jiayun/CS131/Project/./sample_submission/server.py", line 17
    "Smith", 12442,
           ^
SyntaxError: invalid syntax
  File "/w/home.27/ee/ugrad/jiayun/CS131/Project/./sample_submission/server.py", line 17
    "Smith", 12442,
           ^
SyntaxError: invalid syntax
  File "/w/home.27/ee/ugrad/jiayun/CS131/Project/./sample_submission/server.py", line 17
    "Smith", 12442,
           ^
SyntaxError: invalid syntax
  File "/w/home.27/ee/ugrad/jiayun/CS131/Project/./sample_submission/server.py", line 17
    "Smith", 12442,
           ^
SyntaxError: invalid syntax
  File "/w/home.27/ee/ugrad/jiayun/CS131/Project/./sample_submission/server.py", line 17
    "Smith", 12442,
           ^
SyntaxError: invalid syntax
  File "/w/home.27/ee/ugrad/jiayun/CS131/Project/./sample_submission/server.py", line 17
    "Smith", 12442,
           ^
SyntaxError: invalid syntax
  File "/w/home.27/ee/ugrad/jiayun/CS131/Project/./sample_submission/server.py", line 17
    "Smith", 12442,
           ^
SyntaxError: invalid syntax
  File "/w/home.27/ee/ugrad/jiayun/CS131/Project/./sample_submission/server.py", line 17
    "Smith", 12442,
           ^
SyntaxError: invalid syntax
  File "/w/home.27/ee/ugrad/jiayun/CS131/Project/./sample_submission/server.py", line 245
    else:
    ^
SyntaxError: invalid syntax
  File "/w/home.27/ee/ugrad/jiayun/CS131/Project/./sample_submission/server.py", line 245
    else:
    ^
SyntaxError: invalid syntax
  File "/w/home.27/ee/ugrad/jiayun/CS131/Project/./sample_submission/server.py", line 245
    else:
    ^
SyntaxError: invalid syntax
  File "/w/home.27/ee/ugrad/jiayun/CS131/Project/./sample_submission/server.py", line 245
    else:
    ^
SyntaxError: invalid syntax
  File "/w/home.27/ee/ugrad/jiayun/CS131/Project/./sample_submission/server.py", line 245
    else:
    ^
SyntaxError: invalid syntax
  File "/w/home.27/ee/ugrad/jiayun/CS131/Project/./sample_submission/server.py", line 245
    else:
    ^
SyntaxError: invalid syntax
  File "/w/home.27/ee/ugrad/jiayun/CS131/Project/./sample_submission/server.py", line 245
    else:
    ^
SyntaxError: invalid syntax
  File "/w/home.27/ee/ugrad/jiayun/CS131/Project/./sample_submission/server.py", line 245
    else:
    ^
SyntaxError: invalid syntax
  File "/w/home.27/ee/ugrad/jiayun/CS131/Project/./sample_submission/server.py", line 245
    else:
    ^
SyntaxError: invalid syntax
  File "/w/home.27/ee/ugrad/jiayun/CS131/Project/./sample_submission/server.py", line 245
    else:
    ^
SyntaxError: invalid syntax
  File "/w/home.27/ee/ugrad/jiayun/CS131/Project/./sample_submission/server.py", line 249
    if not isinstance(newMsg, type(None))
                                         ^
SyntaxError: invalid syntax
  File "/w/home.27/ee/ugrad/jiayun/CS131/Project/./sample_submission/server.py", line 249
    if not isinstance(newMsg, type(None))
                                         ^
SyntaxError: invalid syntax
  File "/w/home.27/ee/ugrad/jiayun/CS131/Project/./sample_submission/server.py", line 249
    if not isinstance(newMsg, type(None))
                                         ^
SyntaxError: invalid syntax
  File "/w/home.27/ee/ugrad/jiayun/CS131/Project/./sample_submission/server.py", line 249
    if not isinstance(newMsg, type(None))
                                         ^
SyntaxError: invalid syntax
  File "/w/home.27/ee/ugrad/jiayun/CS131/Project/./sample_submission/server.py", line 249
    if not isinstance(newMsg, type(None))
                                         ^
SyntaxError: invalid syntax
Traceback (most recent call last):
  File "/w/home.27/ee/ugrad/jiayun/CS131/Project/./sample_submission/server.py", line 324, in <module>
    main()
  File "/w/home.27/ee/ugrad/jiayun/CS131/Project/./sample_submission/server.py", line 319, in main
    asyncio.run(server.run_forever())
  File "/usr/local/cs/Python-3.9.0/lib/python3.9/asyncio/runners.py", line 44, in run
    return loop.run_until_complete(main)
  File "/usr/local/cs/Python-3.9.0/lib/python3.9/asyncio/base_events.py", line 642, in run_until_complete
    return future.result()
  File "/w/home.27/ee/ugrad/jiayun/CS131/Project/./sample_submission/server.py", line 287, in run_forever
    server = await asyncio.start_server(self.handle_echo, self.ip, self.port)
  File "/usr/local/cs/Python-3.9.0/lib/python3.9/asyncio/streams.py", line 94, in start_server
    return await loop.create_server(factory, host, port, **kwds)
  File "/usr/local/cs/Python-3.9.0/lib/python3.9/asyncio/base_events.py", line 1494, in create_server
    raise OSError(err.errno, 'error while attempting '
OSError: [Errno 98] error while attempting to bind on address ('127.0.0.1', 12441): address already in use
Traceback (most recent call last):
  File "/w/home.27/ee/ugrad/jiayun/CS131/Project/./sample_submission/server.py", line 324, in <module>
    main()
  File "/w/home.27/ee/ugrad/jiayun/CS131/Project/./sample_submission/server.py", line 319, in main
    asyncio.run(server.run_forever())
  File "/usr/local/cs/Python-3.9.0/lib/python3.9/asyncio/runners.py", line 44, in run
    return loop.run_until_complete(main)
  File "/usr/local/cs/Python-3.9.0/lib/python3.9/asyncio/base_events.py", line 642, in run_until_complete
    return future.result()
  File "/w/home.27/ee/ugrad/jiayun/CS131/Project/./sample_submission/server.py", line 287, in run_forever
    server = await asyncio.start_server(self.handle_echo, self.ip, self.port)
  File "/usr/local/cs/Python-3.9.0/lib/python3.9/asyncio/streams.py", line 94, in start_server
    return await loop.create_server(factory, host, port, **kwds)
  File "/usr/local/cs/Python-3.9.0/lib/python3.9/asyncio/base_events.py", line 1494, in create_server
    raise OSError(err.errno, 'error while attempting '
OSError: [Errno 98] error while attempting to bind on address ('127.0.0.1', 12442): address already in use
Traceback (most recent call last):
  File "/w/home.27/ee/ugrad/jiayun/CS131/Project/./sample_submission/server.py", line 324, in <module>
    main()
  File "/w/home.27/ee/ugrad/jiayun/CS131/Project/./sample_submission/server.py", line 319, in main
    asyncio.run(server.run_forever())
  File "/usr/local/cs/Python-3.9.0/lib/python3.9/asyncio/runners.py", line 44, in run
    return loop.run_until_complete(main)
  File "/usr/local/cs/Python-3.9.0/lib/python3.9/asyncio/base_events.py", line 642, in run_until_complete
    return future.result()
  File "/w/home.27/ee/ugrad/jiayun/CS131/Project/./sample_submission/server.py", line 287, in run_forever
    server = await asyncio.start_server(self.handle_echo, self.ip, self.port)
  File "/usr/local/cs/Python-3.9.0/lib/python3.9/asyncio/streams.py", line 94, in start_server
    return await loop.create_server(factory, host, port, **kwds)
  File "/usr/local/cs/Python-3.9.0/lib/python3.9/asyncio/base_events.py", line 1494, in create_server
    raise OSError(err.errno, 'error while attempting '
OSError: [Errno 98] error while attempting to bind on address ('127.0.0.1', 12443): address already in use
Traceback (most recent call last):
  File "/w/home.27/ee/ugrad/jiayun/CS131/Project/./sample_submission/server.py", line 324, in <module>
    main()
  File "/w/home.27/ee/ugrad/jiayun/CS131/Project/./sample_submission/server.py", line 319, in main
    asyncio.run(server.run_forever())
  File "/usr/local/cs/Python-3.9.0/lib/python3.9/asyncio/runners.py", line 44, in run
    return loop.run_until_complete(main)
  File "/usr/local/cs/Python-3.9.0/lib/python3.9/asyncio/base_events.py", line 642, in run_until_complete
    return future.result()
  File "/w/home.27/ee/ugrad/jiayun/CS131/Project/./sample_submission/server.py", line 287, in run_forever
    server = await asyncio.start_server(self.handle_echo, self.ip, self.port)
  File "/usr/local/cs/Python-3.9.0/lib/python3.9/asyncio/streams.py", line 94, in start_server
    return await loop.create_server(factory, host, port, **kwds)
  File "/usr/local/cs/Python-3.9.0/lib/python3.9/asyncio/base_events.py", line 1494, in create_server
    raise OSError(err.errno, 'error while attempting '
OSError: [Errno 98] error while attempting to bind on address ('127.0.0.1', 12444): address already in use
Traceback (most recent call last):
  File "/w/home.27/ee/ugrad/jiayun/CS131/Project/./sample_submission/server.py", line 324, in <module>
    main()
  File "/w/home.27/ee/ugrad/jiayun/CS131/Project/./sample_submission/server.py", line 319, in main
    asyncio.run(server.run_forever())
  File "/usr/local/cs/Python-3.9.0/lib/python3.9/asyncio/runners.py", line 44, in run
    return loop.run_until_complete(main)
  File "/usr/local/cs/Python-3.9.0/lib/python3.9/asyncio/base_events.py", line 642, in run_until_complete
    return future.result()
  File "/w/home.27/ee/ugrad/jiayun/CS131/Project/./sample_submission/server.py", line 287, in run_forever
    server = await asyncio.start_server(self.handle_echo, self.ip, self.port)
  File "/usr/local/cs/Python-3.9.0/lib/python3.9/asyncio/streams.py", line 94, in start_server
    return await loop.create_server(factory, host, port, **kwds)
  File "/usr/local/cs/Python-3.9.0/lib/python3.9/asyncio/base_events.py", line 1494, in create_server
    raise OSError(err.errno, 'error while attempting '
OSError: [Errno 98] error while attempting to bind on address ('127.0.0.1', 12440): address already in use
Traceback (most recent call last):
  File "/w/home.27/ee/ugrad/jiayun/CS131/Project/./sample_submission/server.py", line 324, in <module>
    main()
  File "/w/home.27/ee/ugrad/jiayun/CS131/Project/./sample_submission/server.py", line 319, in main
    asyncio.run(server.run_forever())
  File "/usr/local/cs/Python-3.9.0/lib/python3.9/asyncio/runners.py", line 44, in run
    return loop.run_until_complete(main)
  File "/usr/local/cs/Python-3.9.0/lib/python3.9/asyncio/base_events.py", line 642, in run_until_complete
    return future.result()
  File "/w/home.27/ee/ugrad/jiayun/CS131/Project/./sample_submission/server.py", line 287, in run_forever
    server = await asyncio.start_server(self.handle_echo, self.ip, self.port)
  File "/usr/local/cs/Python-3.9.0/lib/python3.9/asyncio/streams.py", line 94, in start_server
    return await loop.create_server(factory, host, port, **kwds)
  File "/usr/local/cs/Python-3.9.0/lib/python3.9/asyncio/base_events.py", line 1494, in create_server
    raise OSError(err.errno, 'error while attempting '
OSError: [Errno 98] error while attempting to bind on address ('127.0.0.1', 12442): address already in use
Traceback (most recent call last):
  File "/w/home.27/ee/ugrad/jiayun/CS131/Project/./sample_submission/server.py", line 324, in <module>
    main()
  File "/w/home.27/ee/ugrad/jiayun/CS131/Project/./sample_submission/server.py", line 319, in main
    asyncio.run(server.run_forever())
  File "/usr/local/cs/Python-3.9.0/lib/python3.9/asyncio/runners.py", line 44, in run
    return loop.run_until_complete(main)
  File "/usr/local/cs/Python-3.9.0/lib/python3.9/asyncio/base_events.py", line 642, in run_until_complete
    return future.result()
  File "/w/home.27/ee/ugrad/jiayun/CS131/Project/./sample_submission/server.py", line 287, in run_forever
    server = await asyncio.start_server(self.handle_echo, self.ip, self.port)
  File "/usr/local/cs/Python-3.9.0/lib/python3.9/asyncio/streams.py", line 94, in start_server
    return await loop.create_server(factory, host, port, **kwds)
  File "/usr/local/cs/Python-3.9.0/lib/python3.9/asyncio/base_events.py", line 1494, in create_server
    raise OSError(err.errno, 'error while attempting '
OSError: [Errno 98] error while attempting to bind on address ('127.0.0.1', 12443): address already in use
Traceback (most recent call last):
  File "/w/home.27/ee/ugrad/jiayun/CS131/Project/./sample_submission/server.py", line 324, in <module>
    main()
  File "/w/home.27/ee/ugrad/jiayun/CS131/Project/./sample_submission/server.py", line 319, in main
    asyncio.run(server.run_forever())
  File "/usr/local/cs/Python-3.9.0/lib/python3.9/asyncio/runners.py", line 44, in run
    return loop.run_until_complete(main)
  File "/usr/local/cs/Python-3.9.0/lib/python3.9/asyncio/base_events.py", line 642, in run_until_complete
    return future.result()
  File "/w/home.27/ee/ugrad/jiayun/CS131/Project/./sample_submission/server.py", line 287, in run_forever
    server = await asyncio.start_server(self.handle_echo, self.ip, self.port)
  File "/usr/local/cs/Python-3.9.0/lib/python3.9/asyncio/streams.py", line 94, in start_server
    return await loop.create_server(factory, host, port, **kwds)
  File "/usr/local/cs/Python-3.9.0/lib/python3.9/asyncio/base_events.py", line 1494, in create_server
    raise OSError(err.errno, 'error while attempting '
OSError: [Errno 98] error while attempting to bind on address ('127.0.0.1', 12444): address already in use
Traceback (most recent call last):
  File "/w/home.27/ee/ugrad/jiayun/CS131/Project/./sample_submission/server.py", line 324, in <module>
    main()
  File "/w/home.27/ee/ugrad/jiayun/CS131/Project/./sample_submission/server.py", line 319, in main
    asyncio.run(server.run_forever())
  File "/usr/local/cs/Python-3.9.0/lib/python3.9/asyncio/runners.py", line 44, in run
    return loop.run_until_complete(main)
  File "/usr/local/cs/Python-3.9.0/lib/python3.9/asyncio/base_events.py", line 642, in run_until_complete
    return future.result()
  File "/w/home.27/ee/ugrad/jiayun/CS131/Project/./sample_submission/server.py", line 287, in run_forever
    server = await asyncio.start_server(self.handle_echo, self.ip, self.port)
  File "/usr/local/cs/Python-3.9.0/lib/python3.9/asyncio/streams.py", line 94, in start_server
    return await loop.create_server(factory, host, port, **kwds)
  File "/usr/local/cs/Python-3.9.0/lib/python3.9/asyncio/base_events.py", line 1494, in create_server
    raise OSError(err.errno, 'error while attempting '
OSError: [Errno 98] error while attempting to bind on address ('127.0.0.1', 12441): address already in use
Traceback (most recent call last):
  File "/w/home.27/ee/ugrad/jiayun/CS131/Project/./sample_submission/server.py", line 324, in <module>
    main()
  File "/w/home.27/ee/ugrad/jiayun/CS131/Project/./sample_submission/server.py", line 319, in main
    asyncio.run(server.run_forever())
  File "/usr/local/cs/Python-3.9.0/lib/python3.9/asyncio/runners.py", line 44, in run
    return loop.run_until_complete(main)
  File "/usr/local/cs/Python-3.9.0/lib/python3.9/asyncio/base_events.py", line 642, in run_until_complete
    return future.result()
  File "/w/home.27/ee/ugrad/jiayun/CS131/Project/./sample_submission/server.py", line 287, in run_forever
    server = await asyncio.start_server(self.handle_echo, self.ip, self.port)
  File "/usr/local/cs/Python-3.9.0/lib/python3.9/asyncio/streams.py", line 94, in start_server
    return await loop.create_server(factory, host, port, **kwds)
  File "/usr/local/cs/Python-3.9.0/lib/python3.9/asyncio/base_events.py", line 1494, in create_server
    raise OSError(err.errno, 'error while attempting '
OSError: [Errno 98] error while attempting to bind on address ('127.0.0.1', 12443): address already in use
Traceback (most recent call last):
  File "/w/home.27/ee/ugrad/jiayun/CS131/Project/./sample_submission/server.py", line 324, in <module>
    main()
  File "/w/home.27/ee/ugrad/jiayun/CS131/Project/./sample_submission/server.py", line 319, in main
    asyncio.run(server.run_forever())
  File "/usr/local/cs/Python-3.9.0/lib/python3.9/asyncio/runners.py", line 44, in run
    return loop.run_until_complete(main)
  File "/usr/local/cs/Python-3.9.0/lib/python3.9/asyncio/base_events.py", line 642, in run_until_complete
    return future.result()
  File "/w/home.27/ee/ugrad/jiayun/CS131/Project/./sample_submission/server.py", line 287, in run_forever
    server = await asyncio.start_server(self.handle_echo, self.ip, self.port)
  File "/usr/local/cs/Python-3.9.0/lib/python3.9/asyncio/streams.py", line 94, in start_server
    return await loop.create_server(factory, host, port, **kwds)
  File "/usr/local/cs/Python-3.9.0/lib/python3.9/asyncio/base_events.py", line 1494, in create_server
    raise OSError(err.errno, 'error while attempting '
OSError: [Errno 98] error while attempting to bind on address ('127.0.0.1', 12444): address already in use
Traceback (most recent call last):
  File "/w/home.27/ee/ugrad/jiayun/CS131/Project/./sample_submission/server.py", line 324, in <module>
    main()
  File "/w/home.27/ee/ugrad/jiayun/CS131/Project/./sample_submission/server.py", line 319, in main
    asyncio.run(server.run_forever())
  File "/usr/local/cs/Python-3.9.0/lib/python3.9/asyncio/runners.py", line 44, in run
    return loop.run_until_complete(main)
  File "/usr/local/cs/Python-3.9.0/lib/python3.9/asyncio/base_events.py", line 642, in run_until_complete
    return future.result()
  File "/w/home.27/ee/ugrad/jiayun/CS131/Project/./sample_submission/server.py", line 287, in run_forever
    server = await asyncio.start_server(self.handle_echo, self.ip, self.port)
  File "/usr/local/cs/Python-3.9.0/lib/python3.9/asyncio/streams.py", line 94, in start_server
    return await loop.create_server(factory, host, port, **kwds)
  File "/usr/local/cs/Python-3.9.0/lib/python3.9/asyncio/base_events.py", line 1494, in create_server
    raise OSError(err.errno, 'error while attempting '
OSError: [Errno 98] error while attempting to bind on address ('127.0.0.1', 12442): address already in use
Traceback (most recent call last):
  File "/w/home.27/ee/ugrad/jiayun/CS131/Project/./sample_submission/server.py", line 324, in <module>
    main()
  File "/w/home.27/ee/ugrad/jiayun/CS131/Project/./sample_submission/server.py", line 319, in main
    asyncio.run(server.run_forever())
  File "/usr/local/cs/Python-3.9.0/lib/python3.9/asyncio/runners.py", line 44, in run
    return loop.run_until_complete(main)
  File "/usr/local/cs/Python-3.9.0/lib/python3.9/asyncio/base_events.py", line 642, in run_until_complete
    return future.result()
  File "/w/home.27/ee/ugrad/jiayun/CS131/Project/./sample_submission/server.py", line 287, in run_forever
    server = await asyncio.start_server(self.handle_echo, self.ip, self.port)
  File "/usr/local/cs/Python-3.9.0/lib/python3.9/asyncio/streams.py", line 94, in start_server
    return await loop.create_server(factory, host, port, **kwds)
  File "/usr/local/cs/Python-3.9.0/lib/python3.9/asyncio/base_events.py", line 1494, in create_server
    raise OSError(err.errno, 'error while attempting '
OSError: [Errno 98] error while attempting to bind on address ('127.0.0.1', 12444): address already in use
Traceback (most recent call last):
  File "/w/home.27/ee/ugrad/jiayun/CS131/Project/./sample_submission/server.py", line 324, in <module>
    main()
  File "/w/home.27/ee/ugrad/jiayun/CS131/Project/./sample_submission/server.py", line 319, in main
    asyncio.run(server.run_forever())
  File "/usr/local/cs/Python-3.9.0/lib/python3.9/asyncio/runners.py", line 44, in run
    return loop.run_until_complete(main)
  File "/usr/local/cs/Python-3.9.0/lib/python3.9/asyncio/base_events.py", line 642, in run_until_complete
    return future.result()
  File "/w/home.27/ee/ugrad/jiayun/CS131/Project/./sample_submission/server.py", line 287, in run_forever
    server = await asyncio.start_server(self.handle_echo, self.ip, self.port)
  File "/usr/local/cs/Python-3.9.0/lib/python3.9/asyncio/streams.py", line 94, in start_server
    return await loop.create_server(factory, host, port, **kwds)
  File "/usr/local/cs/Python-3.9.0/lib/python3.9/asyncio/base_events.py", line 1494, in create_server
    raise OSError(err.errno, 'error while attempting '
OSError: [Errno 98] error while attempting to bind on address ('127.0.0.1', 12443): address already in use
Traceback (most recent call last):
  File "/w/home.27/ee/ugrad/jiayun/CS131/Project/./sample_submission/server.py", line 324, in <module>
    main()
  File "/w/home.27/ee/ugrad/jiayun/CS131/Project/./sample_submission/server.py", line 319, in main
    asyncio.run(server.run_forever())
  File "/usr/local/cs/Python-3.9.0/lib/python3.9/asyncio/runners.py", line 44, in run
    return loop.run_until_complete(main)
  File "/usr/local/cs/Python-3.9.0/lib/python3.9/asyncio/base_events.py", line 642, in run_until_complete
    return future.result()
  File "/w/home.27/ee/ugrad/jiayun/CS131/Project/./sample_submission/server.py", line 287, in run_forever
    server = await asyncio.start_server(self.handle_echo, self.ip, self.port)
  File "/usr/local/cs/Python-3.9.0/lib/python3.9/asyncio/streams.py", line 94, in start_server
    return await loop.create_server(factory, host, port, **kwds)
  File "/usr/local/cs/Python-3.9.0/lib/python3.9/asyncio/base_events.py", line 1494, in create_server
    raise OSError(err.errno, 'error while attempting '
OSError: [Errno 98] error while attempting to bind on address ('127.0.0.1', 12440): address already in use
Traceback (most recent call last):
  File "/w/home.27/ee/ugrad/jiayun/CS131/Project/./sample_submission/server.py", line 324, in <module>
    main()
  File "/w/home.27/ee/ugrad/jiayun/CS131/Project/./sample_submission/server.py", line 319, in main
    asyncio.run(server.run_forever())
  File "/usr/local/cs/Python-3.9.0/lib/python3.9/asyncio/runners.py", line 44, in run
    return loop.run_until_complete(main)
  File "/usr/local/cs/Python-3.9.0/lib/python3.9/asyncio/base_events.py", line 642, in run_until_complete
    return future.result()
  File "/w/home.27/ee/ugrad/jiayun/CS131/Project/./sample_submission/server.py", line 287, in run_forever
    server = await asyncio.start_server(self.handle_echo, self.ip, self.port)
  File "/usr/local/cs/Python-3.9.0/lib/python3.9/asyncio/streams.py", line 94, in start_server
    return await loop.create_server(factory, host, port, **kwds)
  File "/usr/local/cs/Python-3.9.0/lib/python3.9/asyncio/base_events.py", line 1494, in create_server
    raise OSError(err.errno, 'error while attempting '
OSError: [Errno 98] error while attempting to bind on address ('127.0.0.1', 12441): address already in use
Traceback (most recent call last):
  File "/w/home.27/ee/ugrad/jiayun/CS131/Project/./sample_submission/server.py", line 324, in <module>
    main()
  File "/w/home.27/ee/ugrad/jiayun/CS131/Project/./sample_submission/server.py", line 319, in main
    asyncio.run(server.run_forever())
  File "/usr/local/cs/Python-3.9.0/lib/python3.9/asyncio/runners.py", line 44, in run
    return loop.run_until_complete(main)
  File "/usr/local/cs/Python-3.9.0/lib/python3.9/asyncio/base_events.py", line 642, in run_until_complete
    return future.result()
  File "/w/home.27/ee/ugrad/jiayun/CS131/Project/./sample_submission/server.py", line 287, in run_forever
    server = await asyncio.start_server(self.handle_echo, self.ip, self.port)
  File "/usr/local/cs/Python-3.9.0/lib/python3.9/asyncio/streams.py", line 94, in start_server
    return await loop.create_server(factory, host, port, **kwds)
  File "/usr/local/cs/Python-3.9.0/lib/python3.9/asyncio/base_events.py", line 1494, in create_server
    raise OSError(err.errno, 'error while attempting '
OSError: [Errno 98] error while attempting to bind on address ('127.0.0.1', 12442): address already in use
Traceback (most recent call last):
  File "/w/home.27/ee/ugrad/jiayun/CS131/Project/./sample_submission/server.py", line 324, in <module>
    main()
  File "/w/home.27/ee/ugrad/jiayun/CS131/Project/./sample_submission/server.py", line 319, in main
    asyncio.run(server.run_forever())
  File "/usr/local/cs/Python-3.9.0/lib/python3.9/asyncio/runners.py", line 44, in run
    return loop.run_until_complete(main)
  File "/usr/local/cs/Python-3.9.0/lib/python3.9/asyncio/base_events.py", line 642, in run_until_complete
    return future.result()
  File "/w/home.27/ee/ugrad/jiayun/CS131/Project/./sample_submission/server.py", line 287, in run_forever
    server = await asyncio.start_server(self.handle_echo, self.ip, self.port)
  File "/usr/local/cs/Python-3.9.0/lib/python3.9/asyncio/streams.py", line 94, in start_server
    return await loop.create_server(factory, host, port, **kwds)
  File "/usr/local/cs/Python-3.9.0/lib/python3.9/asyncio/base_events.py", line 1494, in create_server
    raise OSError(err.errno, 'error while attempting '
OSError: [Errno 98] error while attempting to bind on address ('127.0.0.1', 12443): address already in use
Traceback (most recent call last):
  File "/w/home.27/ee/ugrad/jiayun/CS131/Project/./sample_submission/server.py", line 324, in <module>
    main()
  File "/w/home.27/ee/ugrad/jiayun/CS131/Project/./sample_submission/server.py", line 319, in main
    asyncio.run(server.run_forever())
  File "/usr/local/cs/Python-3.9.0/lib/python3.9/asyncio/runners.py", line 44, in run
    return loop.run_until_complete(main)
  File "/usr/local/cs/Python-3.9.0/lib/python3.9/asyncio/base_events.py", line 642, in run_until_complete
    return future.result()
  File "/w/home.27/ee/ugrad/jiayun/CS131/Project/./sample_submission/server.py", line 287, in run_forever
    server = await asyncio.start_server(self.handle_echo, self.ip, self.port)
  File "/usr/local/cs/Python-3.9.0/lib/python3.9/asyncio/streams.py", line 94, in start_server
    return await loop.create_server(factory, host, port, **kwds)
  File "/usr/local/cs/Python-3.9.0/lib/python3.9/asyncio/base_events.py", line 1494, in create_server
    raise OSError(err.errno, 'error while attempting '
OSError: [Errno 98] error while attempting to bind on address ('127.0.0.1', 12444): address already in use
Traceback (most recent call last):
  File "/w/home.27/ee/ugrad/jiayun/CS131/Project/./sample_submission/server.py", line 324, in <module>
    main()
  File "/w/home.27/ee/ugrad/jiayun/CS131/Project/./sample_submission/server.py", line 319, in main
    asyncio.run(server.run_forever())
  File "/usr/local/cs/Python-3.9.0/lib/python3.9/asyncio/runners.py", line 44, in run
    return loop.run_until_complete(main)
  File "/usr/local/cs/Python-3.9.0/lib/python3.9/asyncio/base_events.py", line 642, in run_until_complete
    return future.result()
  File "/w/home.27/ee/ugrad/jiayun/CS131/Project/./sample_submission/server.py", line 287, in run_forever
    server = await asyncio.start_server(self.handle_echo, self.ip, self.port)
  File "/usr/local/cs/Python-3.9.0/lib/python3.9/asyncio/streams.py", line 94, in start_server
    return await loop.create_server(factory, host, port, **kwds)
  File "/usr/local/cs/Python-3.9.0/lib/python3.9/asyncio/base_events.py", line 1494, in create_server
    raise OSError(err.errno, 'error while attempting '
OSError: [Errno 98] error while attempting to bind on address ('127.0.0.1', 12441): address already in use
Traceback (most recent call last):
  File "/w/home.27/ee/ugrad/jiayun/CS131/Project/./sample_submission/server.py", line 324, in <module>
    main()
  File "/w/home.27/ee/ugrad/jiayun/CS131/Project/./sample_submission/server.py", line 319, in main
    asyncio.run(server.run_forever())
  File "/usr/local/cs/Python-3.9.0/lib/python3.9/asyncio/runners.py", line 44, in run
    return loop.run_until_complete(main)
  File "/usr/local/cs/Python-3.9.0/lib/python3.9/asyncio/base_events.py", line 642, in run_until_complete
    return future.result()
  File "/w/home.27/ee/ugrad/jiayun/CS131/Project/./sample_submission/server.py", line 287, in run_forever
    server = await asyncio.start_server(self.handle_echo, self.ip, self.port)
  File "/usr/local/cs/Python-3.9.0/lib/python3.9/asyncio/streams.py", line 94, in start_server
    return await loop.create_server(factory, host, port, **kwds)
  File "/usr/local/cs/Python-3.9.0/lib/python3.9/asyncio/base_events.py", line 1494, in create_server
    raise OSError(err.errno, 'error while attempting '
OSError: [Errno 98] error while attempting to bind on address ('127.0.0.1', 12442): address already in use
Traceback (most recent call last):
  File "/w/home.27/ee/ugrad/jiayun/CS131/Project/./sample_submission/server.py", line 324, in <module>
    main()
  File "/w/home.27/ee/ugrad/jiayun/CS131/Project/./sample_submission/server.py", line 319, in main
    asyncio.run(server.run_forever())
  File "/usr/local/cs/Python-3.9.0/lib/python3.9/asyncio/runners.py", line 44, in run
    return loop.run_until_complete(main)
  File "/usr/local/cs/Python-3.9.0/lib/python3.9/asyncio/base_events.py", line 642, in run_until_complete
    return future.result()
  File "/w/home.27/ee/ugrad/jiayun/CS131/Project/./sample_submission/server.py", line 287, in run_forever
    server = await asyncio.start_server(self.handle_echo, self.ip, self.port)
  File "/usr/local/cs/Python-3.9.0/lib/python3.9/asyncio/streams.py", line 94, in start_server
    return await loop.create_server(factory, host, port, **kwds)
  File "/usr/local/cs/Python-3.9.0/lib/python3.9/asyncio/base_events.py", line 1494, in create_server
    raise OSError(err.errno, 'error while attempting '
OSError: [Errno 98] error while attempting to bind on address ('127.0.0.1', 12443): address already in use
Traceback (most recent call last):
  File "/w/home.27/ee/ugrad/jiayun/CS131/Project/./sample_submission/server.py", line 324, in <module>
    main()
  File "/w/home.27/ee/ugrad/jiayun/CS131/Project/./sample_submission/server.py", line 319, in main
    asyncio.run(server.run_forever())
  File "/usr/local/cs/Python-3.9.0/lib/python3.9/asyncio/runners.py", line 44, in run
    return loop.run_until_complete(main)
  File "/usr/local/cs/Python-3.9.0/lib/python3.9/asyncio/base_events.py", line 642, in run_until_complete
    return future.result()
  File "/w/home.27/ee/ugrad/jiayun/CS131/Project/./sample_submission/server.py", line 287, in run_forever
    server = await asyncio.start_server(self.handle_echo, self.ip, self.port)
  File "/usr/local/cs/Python-3.9.0/lib/python3.9/asyncio/streams.py", line 94, in start_server
    return await loop.create_server(factory, host, port, **kwds)
  File "/usr/local/cs/Python-3.9.0/lib/python3.9/asyncio/base_events.py", line 1494, in create_server
    raise OSError(err.errno, 'error while attempting '
OSError: [Errno 98] error while attempting to bind on address ('127.0.0.1', 12444): address already in use
Traceback (most recent call last):
  File "/w/home.27/ee/ugrad/jiayun/CS131/Project/./sample_submission/server.py", line 324, in <module>
    main()
  File "/w/home.27/ee/ugrad/jiayun/CS131/Project/./sample_submission/server.py", line 319, in main
    asyncio.run(server.run_forever())
  File "/usr/local/cs/Python-3.9.0/lib/python3.9/asyncio/runners.py", line 44, in run
    return loop.run_until_complete(main)
  File "/usr/local/cs/Python-3.9.0/lib/python3.9/asyncio/base_events.py", line 642, in run_until_complete
    return future.result()
  File "/w/home.27/ee/ugrad/jiayun/CS131/Project/./sample_submission/server.py", line 287, in run_forever
    server = await asyncio.start_server(self.handle_echo, self.ip, self.port)
  File "/usr/local/cs/Python-3.9.0/lib/python3.9/asyncio/streams.py", line 94, in start_server
    return await loop.create_server(factory, host, port, **kwds)
  File "/usr/local/cs/Python-3.9.0/lib/python3.9/asyncio/base_events.py", line 1494, in create_server
    raise OSError(err.errno, 'error while attempting '
OSError: [Errno 98] error while attempting to bind on address ('127.0.0.1', 12440): address already in use
Traceback (most recent call last):
  File "/w/home.27/ee/ugrad/jiayun/CS131/Project/./sample_submission/server.py", line 324, in <module>
    main()
  File "/w/home.27/ee/ugrad/jiayun/CS131/Project/./sample_submission/server.py", line 319, in main
    asyncio.run(server.run_forever())
  File "/usr/local/cs/Python-3.9.0/lib/python3.9/asyncio/runners.py", line 44, in run
    return loop.run_until_complete(main)
  File "/usr/local/cs/Python-3.9.0/lib/python3.9/asyncio/base_events.py", line 642, in run_until_complete
    return future.result()
  File "/w/home.27/ee/ugrad/jiayun/CS131/Project/./sample_submission/server.py", line 287, in run_forever
    server = await asyncio.start_server(self.handle_echo, self.ip, self.port)
  File "/usr/local/cs/Python-3.9.0/lib/python3.9/asyncio/streams.py", line 94, in start_server
    return await loop.create_server(factory, host, port, **kwds)
  File "/usr/local/cs/Python-3.9.0/lib/python3.9/asyncio/base_events.py", line 1494, in create_server
    raise OSError(err.errno, 'error while attempting '
OSError: [Errno 98] error while attempting to bind on address ('127.0.0.1', 12442): address already in use
Traceback (most recent call last):
  File "/w/home.27/ee/ugrad/jiayun/CS131/Project/./sample_submission/server.py", line 324, in <module>
    main()
  File "/w/home.27/ee/ugrad/jiayun/CS131/Project/./sample_submission/server.py", line 319, in main
    asyncio.run(server.run_forever())
  File "/usr/local/cs/Python-3.9.0/lib/python3.9/asyncio/runners.py", line 44, in run
    return loop.run_until_complete(main)
  File "/usr/local/cs/Python-3.9.0/lib/python3.9/asyncio/base_events.py", line 642, in run_until_complete
    return future.result()
  File "/w/home.27/ee/ugrad/jiayun/CS131/Project/./sample_submission/server.py", line 287, in run_forever
    server = await asyncio.start_server(self.handle_echo, self.ip, self.port)
  File "/usr/local/cs/Python-3.9.0/lib/python3.9/asyncio/streams.py", line 94, in start_server
    return await loop.create_server(factory, host, port, **kwds)
  File "/usr/local/cs/Python-3.9.0/lib/python3.9/asyncio/base_events.py", line 1494, in create_server
    raise OSError(err.errno, 'error while attempting '
OSError: [Errno 98] error while attempting to bind on address ('127.0.0.1', 12443): address already in use
Traceback (most recent call last):
  File "/w/home.27/ee/ugrad/jiayun/CS131/Project/./sample_submission/server.py", line 324, in <module>
    main()
  File "/w/home.27/ee/ugrad/jiayun/CS131/Project/./sample_submission/server.py", line 319, in main
    asyncio.run(server.run_forever())
  File "/usr/local/cs/Python-3.9.0/lib/python3.9/asyncio/runners.py", line 44, in run
    return loop.run_until_complete(main)
  File "/usr/local/cs/Python-3.9.0/lib/python3.9/asyncio/base_events.py", line 642, in run_until_complete
    return future.result()
  File "/w/home.27/ee/ugrad/jiayun/CS131/Project/./sample_submission/server.py", line 287, in run_forever
    server = await asyncio.start_server(self.handle_echo, self.ip, self.port)
  File "/usr/local/cs/Python-3.9.0/lib/python3.9/asyncio/streams.py", line 94, in start_server
    return await loop.create_server(factory, host, port, **kwds)
  File "/usr/local/cs/Python-3.9.0/lib/python3.9/asyncio/base_events.py", line 1494, in create_server
    raise OSError(err.errno, 'error while attempting '
OSError: [Errno 98] error while attempting to bind on address ('127.0.0.1', 12444): address already in use
Traceback (most recent call last):
  File "/w/home.27/ee/ugrad/jiayun/CS131/Project/./sample_submission/server.py", line 324, in <module>
    main()
  File "/w/home.27/ee/ugrad/jiayun/CS131/Project/./sample_submission/server.py", line 319, in main
    asyncio.run(server.run_forever())
  File "/usr/local/cs/Python-3.9.0/lib/python3.9/asyncio/runners.py", line 44, in run
    return loop.run_until_complete(main)
  File "/usr/local/cs/Python-3.9.0/lib/python3.9/asyncio/base_events.py", line 642, in run_until_complete
    return future.result()
  File "/w/home.27/ee/ugrad/jiayun/CS131/Project/./sample_submission/server.py", line 287, in run_forever
    server = await asyncio.start_server(self.handle_echo, self.ip, self.port)
  File "/usr/local/cs/Python-3.9.0/lib/python3.9/asyncio/streams.py", line 94, in start_server
    return await loop.create_server(factory, host, port, **kwds)
  File "/usr/local/cs/Python-3.9.0/lib/python3.9/asyncio/base_events.py", line 1494, in create_server
    raise OSError(err.errno, 'error while attempting '
OSError: [Errno 98] error while attempting to bind on address ('127.0.0.1', 12441): address already in use
Traceback (most recent call last):
  File "/w/home.27/ee/ugrad/jiayun/CS131/Project/./sample_submission/server.py", line 324, in <module>
    main()
  File "/w/home.27/ee/ugrad/jiayun/CS131/Project/./sample_submission/server.py", line 319, in main
    asyncio.run(server.run_forever())
  File "/usr/local/cs/Python-3.9.0/lib/python3.9/asyncio/runners.py", line 44, in run
    return loop.run_until_complete(main)
  File "/usr/local/cs/Python-3.9.0/lib/python3.9/asyncio/base_events.py", line 642, in run_until_complete
    return future.result()
  File "/w/home.27/ee/ugrad/jiayun/CS131/Project/./sample_submission/server.py", line 287, in run_forever
    server = await asyncio.start_server(self.handle_echo, self.ip, self.port)
  File "/usr/local/cs/Python-3.9.0/lib/python3.9/asyncio/streams.py", line 94, in start_server
    return await loop.create_server(factory, host, port, **kwds)
  File "/usr/local/cs/Python-3.9.0/lib/python3.9/asyncio/base_events.py", line 1494, in create_server
    raise OSError(err.errno, 'error while attempting '
OSError: [Errno 98] error while attempting to bind on address ('127.0.0.1', 12443): address already in use
Traceback (most recent call last):
  File "/w/home.27/ee/ugrad/jiayun/CS131/Project/./sample_submission/server.py", line 324, in <module>
    main()
  File "/w/home.27/ee/ugrad/jiayun/CS131/Project/./sample_submission/server.py", line 319, in main
    asyncio.run(server.run_forever())
  File "/usr/local/cs/Python-3.9.0/lib/python3.9/asyncio/runners.py", line 44, in run
    return loop.run_until_complete(main)
  File "/usr/local/cs/Python-3.9.0/lib/python3.9/asyncio/base_events.py", line 642, in run_until_complete
    return future.result()
  File "/w/home.27/ee/ugrad/jiayun/CS131/Project/./sample_submission/server.py", line 287, in run_forever
    server = await asyncio.start_server(self.handle_echo, self.ip, self.port)
  File "/usr/local/cs/Python-3.9.0/lib/python3.9/asyncio/streams.py", line 94, in start_server
    return await loop.create_server(factory, host, port, **kwds)
  File "/usr/local/cs/Python-3.9.0/lib/python3.9/asyncio/base_events.py", line 1494, in create_server
    raise OSError(err.errno, 'error while attempting '
OSError: [Errno 98] error while attempting to bind on address ('127.0.0.1', 12444): address already in use
Traceback (most recent call last):
  File "/w/home.27/ee/ugrad/jiayun/CS131/Project/./sample_submission/server.py", line 324, in <module>
    main()
  File "/w/home.27/ee/ugrad/jiayun/CS131/Project/./sample_submission/server.py", line 319, in main
    asyncio.run(server.run_forever())
  File "/usr/local/cs/Python-3.9.0/lib/python3.9/asyncio/runners.py", line 44, in run
    return loop.run_until_complete(main)
  File "/usr/local/cs/Python-3.9.0/lib/python3.9/asyncio/base_events.py", line 642, in run_until_complete
    return future.result()
  File "/w/home.27/ee/ugrad/jiayun/CS131/Project/./sample_submission/server.py", line 287, in run_forever
    server = await asyncio.start_server(self.handle_echo, self.ip, self.port)
  File "/usr/local/cs/Python-3.9.0/lib/python3.9/asyncio/streams.py", line 94, in start_server
    return await loop.create_server(factory, host, port, **kwds)
  File "/usr/local/cs/Python-3.9.0/lib/python3.9/asyncio/base_events.py", line 1494, in create_server
    raise OSError(err.errno, 'error while attempting '
OSError: [Errno 98] error while attempting to bind on address ('127.0.0.1', 12442): address already in use
Traceback (most recent call last):
  File "/w/home.27/ee/ugrad/jiayun/CS131/Project/./sample_submission/server.py", line 324, in <module>
    main()
  File "/w/home.27/ee/ugrad/jiayun/CS131/Project/./sample_submission/server.py", line 319, in main
    asyncio.run(server.run_forever())
  File "/usr/local/cs/Python-3.9.0/lib/python3.9/asyncio/runners.py", line 44, in run
    return loop.run_until_complete(main)
  File "/usr/local/cs/Python-3.9.0/lib/python3.9/asyncio/base_events.py", line 642, in run_until_complete
    return future.result()
  File "/w/home.27/ee/ugrad/jiayun/CS131/Project/./sample_submission/server.py", line 287, in run_forever
    server = await asyncio.start_server(self.handle_echo, self.ip, self.port)
  File "/usr/local/cs/Python-3.9.0/lib/python3.9/asyncio/streams.py", line 94, in start_server
    return await loop.create_server(factory, host, port, **kwds)
  File "/usr/local/cs/Python-3.9.0/lib/python3.9/asyncio/base_events.py", line 1494, in create_server
    raise OSError(err.errno, 'error while attempting '
OSError: [Errno 98] error while attempting to bind on address ('127.0.0.1', 12444): address already in use
Traceback (most recent call last):
  File "/w/home.27/ee/ugrad/jiayun/CS131/Project/./sample_submission/server.py", line 324, in <module>
    main()
  File "/w/home.27/ee/ugrad/jiayun/CS131/Project/./sample_submission/server.py", line 319, in main
    asyncio.run(server.run_forever())
  File "/usr/local/cs/Python-3.9.0/lib/python3.9/asyncio/runners.py", line 44, in run
    return loop.run_until_complete(main)
  File "/usr/local/cs/Python-3.9.0/lib/python3.9/asyncio/base_events.py", line 642, in run_until_complete
    return future.result()
  File "/w/home.27/ee/ugrad/jiayun/CS131/Project/./sample_submission/server.py", line 287, in run_forever
    server = await asyncio.start_server(self.handle_echo, self.ip, self.port)
  File "/usr/local/cs/Python-3.9.0/lib/python3.9/asyncio/streams.py", line 94, in start_server
    return await loop.create_server(factory, host, port, **kwds)
  File "/usr/local/cs/Python-3.9.0/lib/python3.9/asyncio/base_events.py", line 1494, in create_server
    raise OSError(err.errno, 'error while attempting '
OSError: [Errno 98] error while attempting to bind on address ('127.0.0.1', 12443): address already in use
Traceback (most recent call last):
  File "/w/home.27/ee/ugrad/jiayun/CS131/Project/./sample_submission/server.py", line 324, in <module>
    main()
  File "/w/home.27/ee/ugrad/jiayun/CS131/Project/./sample_submission/server.py", line 319, in main
    asyncio.run(server.run_forever())
  File "/usr/local/cs/Python-3.9.0/lib/python3.9/asyncio/runners.py", line 44, in run
    return loop.run_until_complete(main)
  File "/usr/local/cs/Python-3.9.0/lib/python3.9/asyncio/base_events.py", line 642, in run_until_complete
    return future.result()
  File "/w/home.27/ee/ugrad/jiayun/CS131/Project/./sample_submission/server.py", line 287, in run_forever
    server = await asyncio.start_server(self.handle_echo, self.ip, self.port)
  File "/usr/local/cs/Python-3.9.0/lib/python3.9/asyncio/streams.py", line 94, in start_server
    return await loop.create_server(factory, host, port, **kwds)
  File "/usr/local/cs/Python-3.9.0/lib/python3.9/asyncio/base_events.py", line 1494, in create_server
    raise OSError(err.errno, 'error while attempting '
OSError: [Errno 98] error while attempting to bind on address ('127.0.0.1', 12440): address already in use
Traceback (most recent call last):
  File "/w/home.27/ee/ugrad/jiayun/CS131/Project/./sample_submission/server.py", line 324, in <module>
    main()
  File "/w/home.27/ee/ugrad/jiayun/CS131/Project/./sample_submission/server.py", line 319, in main
    asyncio.run(server.run_forever())
  File "/usr/local/cs/Python-3.9.0/lib/python3.9/asyncio/runners.py", line 44, in run
    return loop.run_until_complete(main)
  File "/usr/local/cs/Python-3.9.0/lib/python3.9/asyncio/base_events.py", line 642, in run_until_complete
    return future.result()
  File "/w/home.27/ee/ugrad/jiayun/CS131/Project/./sample_submission/server.py", line 287, in run_forever
    server = await asyncio.start_server(self.handle_echo, self.ip, self.port)
  File "/usr/local/cs/Python-3.9.0/lib/python3.9/asyncio/streams.py", line 94, in start_server
    return await loop.create_server(factory, host, port, **kwds)
  File "/usr/local/cs/Python-3.9.0/lib/python3.9/asyncio/base_events.py", line 1494, in create_server
    raise OSError(err.errno, 'error while attempting '
OSError: [Errno 98] error while attempting to bind on address ('127.0.0.1', 12441): address already in use
Traceback (most recent call last):
  File "/w/home.27/ee/ugrad/jiayun/CS131/Project/./sample_submission/server.py", line 324, in <module>
    main()
  File "/w/home.27/ee/ugrad/jiayun/CS131/Project/./sample_submission/server.py", line 319, in main
    asyncio.run(server.run_forever())
  File "/usr/local/cs/Python-3.9.0/lib/python3.9/asyncio/runners.py", line 44, in run
    return loop.run_until_complete(main)
  File "/usr/local/cs/Python-3.9.0/lib/python3.9/asyncio/base_events.py", line 642, in run_until_complete
    return future.result()
  File "/w/home.27/ee/ugrad/jiayun/CS131/Project/./sample_submission/server.py", line 287, in run_forever
    server = await asyncio.start_server(self.handle_echo, self.ip, self.port)
  File "/usr/local/cs/Python-3.9.0/lib/python3.9/asyncio/streams.py", line 94, in start_server
    return await loop.create_server(factory, host, port, **kwds)
  File "/usr/local/cs/Python-3.9.0/lib/python3.9/asyncio/base_events.py", line 1494, in create_server
    raise OSError(err.errno, 'error while attempting '
OSError: [Errno 98] error while attempting to bind on address ('127.0.0.1', 12442): address already in use
Traceback (most recent call last):
  File "/w/home.27/ee/ugrad/jiayun/CS131/Project/./sample_submission/server.py", line 324, in <module>
    main()
  File "/w/home.27/ee/ugrad/jiayun/CS131/Project/./sample_submission/server.py", line 319, in main
    asyncio.run(server.run_forever())
  File "/usr/local/cs/Python-3.9.0/lib/python3.9/asyncio/runners.py", line 44, in run
    return loop.run_until_complete(main)
  File "/usr/local/cs/Python-3.9.0/lib/python3.9/asyncio/base_events.py", line 642, in run_until_complete
    return future.result()
  File "/w/home.27/ee/ugrad/jiayun/CS131/Project/./sample_submission/server.py", line 287, in run_forever
    server = await asyncio.start_server(self.handle_echo, self.ip, self.port)
  File "/usr/local/cs/Python-3.9.0/lib/python3.9/asyncio/streams.py", line 94, in start_server
    return await loop.create_server(factory, host, port, **kwds)
  File "/usr/local/cs/Python-3.9.0/lib/python3.9/asyncio/base_events.py", line 1494, in create_server
    raise OSError(err.errno, 'error while attempting '
OSError: [Errno 98] error while attempting to bind on address ('127.0.0.1', 12443): address already in use
Traceback (most recent call last):
  File "/w/home.27/ee/ugrad/jiayun/CS131/Project/./sample_submission/server.py", line 324, in <module>
    main()
  File "/w/home.27/ee/ugrad/jiayun/CS131/Project/./sample_submission/server.py", line 319, in main
    asyncio.run(server.run_forever())
  File "/usr/local/cs/Python-3.9.0/lib/python3.9/asyncio/runners.py", line 44, in run
    return loop.run_until_complete(main)
  File "/usr/local/cs/Python-3.9.0/lib/python3.9/asyncio/base_events.py", line 642, in run_until_complete
    return future.result()
  File "/w/home.27/ee/ugrad/jiayun/CS131/Project/./sample_submission/server.py", line 287, in run_forever
    server = await asyncio.start_server(self.handle_echo, self.ip, self.port)
  File "/usr/local/cs/Python-3.9.0/lib/python3.9/asyncio/streams.py", line 94, in start_server
    return await loop.create_server(factory, host, port, **kwds)
  File "/usr/local/cs/Python-3.9.0/lib/python3.9/asyncio/base_events.py", line 1494, in create_server
    raise OSError(err.errno, 'error while attempting '
OSError: [Errno 98] error while attempting to bind on address ('127.0.0.1', 12444): address already in use
Traceback (most recent call last):
  File "/w/home.27/ee/ugrad/jiayun/CS131/Project/./sample_submission/server.py", line 324, in <module>
    main()
  File "/w/home.27/ee/ugrad/jiayun/CS131/Project/./sample_submission/server.py", line 319, in main
    asyncio.run(server.run_forever())
  File "/usr/local/cs/Python-3.9.0/lib/python3.9/asyncio/runners.py", line 44, in run
    return loop.run_until_complete(main)
  File "/usr/local/cs/Python-3.9.0/lib/python3.9/asyncio/base_events.py", line 642, in run_until_complete
    return future.result()
  File "/w/home.27/ee/ugrad/jiayun/CS131/Project/./sample_submission/server.py", line 287, in run_forever
    server = await asyncio.start_server(self.handle_echo, self.ip, self.port)
  File "/usr/local/cs/Python-3.9.0/lib/python3.9/asyncio/streams.py", line 94, in start_server
    return await loop.create_server(factory, host, port, **kwds)
  File "/usr/local/cs/Python-3.9.0/lib/python3.9/asyncio/base_events.py", line 1494, in create_server
    raise OSError(err.errno, 'error while attempting '
OSError: [Errno 98] error while attempting to bind on address ('127.0.0.1', 12441): address already in use
Traceback (most recent call last):
  File "/w/home.27/ee/ugrad/jiayun/CS131/Project/./sample_submission/server.py", line 324, in <module>
    main()
  File "/w/home.27/ee/ugrad/jiayun/CS131/Project/./sample_submission/server.py", line 319, in main
    asyncio.run(server.run_forever())
  File "/usr/local/cs/Python-3.9.0/lib/python3.9/asyncio/runners.py", line 44, in run
    return loop.run_until_complete(main)
  File "/usr/local/cs/Python-3.9.0/lib/python3.9/asyncio/base_events.py", line 642, in run_until_complete
    return future.result()
  File "/w/home.27/ee/ugrad/jiayun/CS131/Project/./sample_submission/server.py", line 287, in run_forever
    server = await asyncio.start_server(self.handle_echo, self.ip, self.port)
  File "/usr/local/cs/Python-3.9.0/lib/python3.9/asyncio/streams.py", line 94, in start_server
    return await loop.create_server(factory, host, port, **kwds)
  File "/usr/local/cs/Python-3.9.0/lib/python3.9/asyncio/base_events.py", line 1494, in create_server
    raise OSError(err.errno, 'error while attempting '
OSError: [Errno 98] error while attempting to bind on address ('127.0.0.1', 12442): address already in use
Traceback (most recent call last):
  File "/w/home.27/ee/ugrad/jiayun/CS131/Project/./sample_submission/server.py", line 324, in <module>
    main()
  File "/w/home.27/ee/ugrad/jiayun/CS131/Project/./sample_submission/server.py", line 319, in main
    asyncio.run(server.run_forever())
  File "/usr/local/cs/Python-3.9.0/lib/python3.9/asyncio/runners.py", line 44, in run
    return loop.run_until_complete(main)
  File "/usr/local/cs/Python-3.9.0/lib/python3.9/asyncio/base_events.py", line 642, in run_until_complete
    return future.result()
  File "/w/home.27/ee/ugrad/jiayun/CS131/Project/./sample_submission/server.py", line 287, in run_forever
    server = await asyncio.start_server(self.handle_echo, self.ip, self.port)
  File "/usr/local/cs/Python-3.9.0/lib/python3.9/asyncio/streams.py", line 94, in start_server
    return await loop.create_server(factory, host, port, **kwds)
  File "/usr/local/cs/Python-3.9.0/lib/python3.9/asyncio/base_events.py", line 1494, in create_server
    raise OSError(err.errno, 'error while attempting '
OSError: [Errno 98] error while attempting to bind on address ('127.0.0.1', 12443): address already in use
Traceback (most recent call last):
  File "/w/home.27/ee/ugrad/jiayun/CS131/Project/./sample_submission/server.py", line 324, in <module>
    main()
  File "/w/home.27/ee/ugrad/jiayun/CS131/Project/./sample_submission/server.py", line 319, in main
    asyncio.run(server.run_forever())
  File "/usr/local/cs/Python-3.9.0/lib/python3.9/asyncio/runners.py", line 44, in run
    return loop.run_until_complete(main)
  File "/usr/local/cs/Python-3.9.0/lib/python3.9/asyncio/base_events.py", line 642, in run_until_complete
    return future.result()
  File "/w/home.27/ee/ugrad/jiayun/CS131/Project/./sample_submission/server.py", line 287, in run_forever
    server = await asyncio.start_server(self.handle_echo, self.ip, self.port)
  File "/usr/local/cs/Python-3.9.0/lib/python3.9/asyncio/streams.py", line 94, in start_server
    return await loop.create_server(factory, host, port, **kwds)
  File "/usr/local/cs/Python-3.9.0/lib/python3.9/asyncio/base_events.py", line 1494, in create_server
    raise OSError(err.errno, 'error while attempting '
OSError: [Errno 98] error while attempting to bind on address ('127.0.0.1', 12444): address already in use
Traceback (most recent call last):
  File "/w/home.27/ee/ugrad/jiayun/CS131/Project/./sample_submission/server.py", line 324, in <module>
    main()
  File "/w/home.27/ee/ugrad/jiayun/CS131/Project/./sample_submission/server.py", line 319, in main
    asyncio.run(server.run_forever())
  File "/usr/local/cs/Python-3.9.0/lib/python3.9/asyncio/runners.py", line 44, in run
    return loop.run_until_complete(main)
  File "/usr/local/cs/Python-3.9.0/lib/python3.9/asyncio/base_events.py", line 642, in run_until_complete
    return future.result()
  File "/w/home.27/ee/ugrad/jiayun/CS131/Project/./sample_submission/server.py", line 287, in run_forever
    server = await asyncio.start_server(self.handle_echo, self.ip, self.port)
  File "/usr/local/cs/Python-3.9.0/lib/python3.9/asyncio/streams.py", line 94, in start_server
    return await loop.create_server(factory, host, port, **kwds)
  File "/usr/local/cs/Python-3.9.0/lib/python3.9/asyncio/base_events.py", line 1494, in create_server
    raise OSError(err.errno, 'error while attempting '
OSError: [Errno 98] error while attempting to bind on address ('127.0.0.1', 12440): address already in use
Traceback (most recent call last):
  File "/w/home.27/ee/ugrad/jiayun/CS131/Project/./sample_submission/server.py", line 324, in <module>
    main()
  File "/w/home.27/ee/ugrad/jiayun/CS131/Project/./sample_submission/server.py", line 319, in main
    asyncio.run(server.run_forever())
  File "/usr/local/cs/Python-3.9.0/lib/python3.9/asyncio/runners.py", line 44, in run
    return loop.run_until_complete(main)
  File "/usr/local/cs/Python-3.9.0/lib/python3.9/asyncio/base_events.py", line 642, in run_until_complete
    return future.result()
  File "/w/home.27/ee/ugrad/jiayun/CS131/Project/./sample_submission/server.py", line 287, in run_forever
    server = await asyncio.start_server(self.handle_echo, self.ip, self.port)
  File "/usr/local/cs/Python-3.9.0/lib/python3.9/asyncio/streams.py", line 94, in start_server
    return await loop.create_server(factory, host, port, **kwds)
  File "/usr/local/cs/Python-3.9.0/lib/python3.9/asyncio/base_events.py", line 1494, in create_server
    raise OSError(err.errno, 'error while attempting '
OSError: [Errno 98] error while attempting to bind on address ('127.0.0.1', 12442): address already in use
Traceback (most recent call last):
  File "/w/home.27/ee/ugrad/jiayun/CS131/Project/./sample_submission/server.py", line 324, in <module>
    main()
  File "/w/home.27/ee/ugrad/jiayun/CS131/Project/./sample_submission/server.py", line 319, in main
    asyncio.run(server.run_forever())
  File "/usr/local/cs/Python-3.9.0/lib/python3.9/asyncio/runners.py", line 44, in run
    return loop.run_until_complete(main)
  File "/usr/local/cs/Python-3.9.0/lib/python3.9/asyncio/base_events.py", line 642, in run_until_complete
    return future.result()
  File "/w/home.27/ee/ugrad/jiayun/CS131/Project/./sample_submission/server.py", line 287, in run_forever
    server = await asyncio.start_server(self.handle_echo, self.ip, self.port)
  File "/usr/local/cs/Python-3.9.0/lib/python3.9/asyncio/streams.py", line 94, in start_server
    return await loop.create_server(factory, host, port, **kwds)
  File "/usr/local/cs/Python-3.9.0/lib/python3.9/asyncio/base_events.py", line 1494, in create_server
    raise OSError(err.errno, 'error while attempting '
OSError: [Errno 98] error while attempting to bind on address ('127.0.0.1', 12443): address already in use
Traceback (most recent call last):
  File "/w/home.27/ee/ugrad/jiayun/CS131/Project/./sample_submission/server.py", line 324, in <module>
    main()
  File "/w/home.27/ee/ugrad/jiayun/CS131/Project/./sample_submission/server.py", line 319, in main
    asyncio.run(server.run_forever())
  File "/usr/local/cs/Python-3.9.0/lib/python3.9/asyncio/runners.py", line 44, in run
    return loop.run_until_complete(main)
  File "/usr/local/cs/Python-3.9.0/lib/python3.9/asyncio/base_events.py", line 642, in run_until_complete
    return future.result()
  File "/w/home.27/ee/ugrad/jiayun/CS131/Project/./sample_submission/server.py", line 287, in run_forever
    server = await asyncio.start_server(self.handle_echo, self.ip, self.port)
  File "/usr/local/cs/Python-3.9.0/lib/python3.9/asyncio/streams.py", line 94, in start_server
    return await loop.create_server(factory, host, port, **kwds)
  File "/usr/local/cs/Python-3.9.0/lib/python3.9/asyncio/base_events.py", line 1494, in create_server
    raise OSError(err.errno, 'error while attempting '
OSError: [Errno 98] error while attempting to bind on address ('127.0.0.1', 12444): address already in use
Traceback (most recent call last):
  File "/w/home.27/ee/ugrad/jiayun/CS131/Project/./sample_submission/server.py", line 324, in <module>
    main()
  File "/w/home.27/ee/ugrad/jiayun/CS131/Project/./sample_submission/server.py", line 319, in main
    asyncio.run(server.run_forever())
  File "/usr/local/cs/Python-3.9.0/lib/python3.9/asyncio/runners.py", line 44, in run
    return loop.run_until_complete(main)
  File "/usr/local/cs/Python-3.9.0/lib/python3.9/asyncio/base_events.py", line 642, in run_until_complete
    return future.result()
  File "/w/home.27/ee/ugrad/jiayun/CS131/Project/./sample_submission/server.py", line 287, in run_forever
    server = await asyncio.start_server(self.handle_echo, self.ip, self.port)
  File "/usr/local/cs/Python-3.9.0/lib/python3.9/asyncio/streams.py", line 94, in start_server
    return await loop.create_server(factory, host, port, **kwds)
  File "/usr/local/cs/Python-3.9.0/lib/python3.9/asyncio/base_events.py", line 1494, in create_server
    raise OSError(err.errno, 'error while attempting '
OSError: [Errno 98] error while attempting to bind on address ('127.0.0.1', 12441): address already in use
Traceback (most recent call last):
  File "/w/home.27/ee/ugrad/jiayun/CS131/Project/./sample_submission/server.py", line 324, in <module>
    main()
  File "/w/home.27/ee/ugrad/jiayun/CS131/Project/./sample_submission/server.py", line 319, in main
    asyncio.run(server.run_forever())
  File "/usr/local/cs/Python-3.9.0/lib/python3.9/asyncio/runners.py", line 44, in run
    return loop.run_until_complete(main)
  File "/usr/local/cs/Python-3.9.0/lib/python3.9/asyncio/base_events.py", line 642, in run_until_complete
    return future.result()
  File "/w/home.27/ee/ugrad/jiayun/CS131/Project/./sample_submission/server.py", line 287, in run_forever
    server = await asyncio.start_server(self.handle_echo, self.ip, self.port)
  File "/usr/local/cs/Python-3.9.0/lib/python3.9/asyncio/streams.py", line 94, in start_server
    return await loop.create_server(factory, host, port, **kwds)
  File "/usr/local/cs/Python-3.9.0/lib/python3.9/asyncio/base_events.py", line 1494, in create_server
    raise OSError(err.errno, 'error while attempting '
OSError: [Errno 98] error while attempting to bind on address ('127.0.0.1', 12443): address already in use
Traceback (most recent call last):
  File "/w/home.27/ee/ugrad/jiayun/CS131/Project/./sample_submission/server.py", line 324, in <module>
    main()
  File "/w/home.27/ee/ugrad/jiayun/CS131/Project/./sample_submission/server.py", line 319, in main
    asyncio.run(server.run_forever())
  File "/usr/local/cs/Python-3.9.0/lib/python3.9/asyncio/runners.py", line 44, in run
    return loop.run_until_complete(main)
  File "/usr/local/cs/Python-3.9.0/lib/python3.9/asyncio/base_events.py", line 642, in run_until_complete
    return future.result()
  File "/w/home.27/ee/ugrad/jiayun/CS131/Project/./sample_submission/server.py", line 287, in run_forever
    server = await asyncio.start_server(self.handle_echo, self.ip, self.port)
  File "/usr/local/cs/Python-3.9.0/lib/python3.9/asyncio/streams.py", line 94, in start_server
    return await loop.create_server(factory, host, port, **kwds)
  File "/usr/local/cs/Python-3.9.0/lib/python3.9/asyncio/base_events.py", line 1494, in create_server
    raise OSError(err.errno, 'error while attempting '
OSError: [Errno 98] error while attempting to bind on address ('127.0.0.1', 12444): address already in use
Traceback (most recent call last):
  File "/w/home.27/ee/ugrad/jiayun/CS131/Project/./sample_submission/server.py", line 324, in <module>
    main()
  File "/w/home.27/ee/ugrad/jiayun/CS131/Project/./sample_submission/server.py", line 319, in main
    asyncio.run(server.run_forever())
  File "/usr/local/cs/Python-3.9.0/lib/python3.9/asyncio/runners.py", line 44, in run
    return loop.run_until_complete(main)
  File "/usr/local/cs/Python-3.9.0/lib/python3.9/asyncio/base_events.py", line 642, in run_until_complete
    return future.result()
  File "/w/home.27/ee/ugrad/jiayun/CS131/Project/./sample_submission/server.py", line 287, in run_forever
    server = await asyncio.start_server(self.handle_echo, self.ip, self.port)
  File "/usr/local/cs/Python-3.9.0/lib/python3.9/asyncio/streams.py", line 94, in start_server
    return await loop.create_server(factory, host, port, **kwds)
  File "/usr/local/cs/Python-3.9.0/lib/python3.9/asyncio/base_events.py", line 1494, in create_server
    raise OSError(err.errno, 'error while attempting '
OSError: [Errno 98] error while attempting to bind on address ('127.0.0.1', 12442): address already in use
Traceback (most recent call last):
  File "/w/home.27/ee/ugrad/jiayun/CS131/Project/./sample_submission/server.py", line 324, in <module>
    main()
  File "/w/home.27/ee/ugrad/jiayun/CS131/Project/./sample_submission/server.py", line 319, in main
    asyncio.run(server.run_forever())
  File "/usr/local/cs/Python-3.9.0/lib/python3.9/asyncio/runners.py", line 44, in run
    return loop.run_until_complete(main)
  File "/usr/local/cs/Python-3.9.0/lib/python3.9/asyncio/base_events.py", line 642, in run_until_complete
    return future.result()
  File "/w/home.27/ee/ugrad/jiayun/CS131/Project/./sample_submission/server.py", line 287, in run_forever
    server = await asyncio.start_server(self.handle_echo, self.ip, self.port)
  File "/usr/local/cs/Python-3.9.0/lib/python3.9/asyncio/streams.py", line 94, in start_server
    return await loop.create_server(factory, host, port, **kwds)
  File "/usr/local/cs/Python-3.9.0/lib/python3.9/asyncio/base_events.py", line 1494, in create_server
    raise OSError(err.errno, 'error while attempting '
OSError: [Errno 98] error while attempting to bind on address ('127.0.0.1', 12444): address already in use
Traceback (most recent call last):
  File "/w/home.27/ee/ugrad/jiayun/CS131/Project/./sample_submission/server.py", line 324, in <module>
    main()
  File "/w/home.27/ee/ugrad/jiayun/CS131/Project/./sample_submission/server.py", line 319, in main
    asyncio.run(server.run_forever())
  File "/usr/local/cs/Python-3.9.0/lib/python3.9/asyncio/runners.py", line 44, in run
    return loop.run_until_complete(main)
  File "/usr/local/cs/Python-3.9.0/lib/python3.9/asyncio/base_events.py", line 642, in run_until_complete
    return future.result()
  File "/w/home.27/ee/ugrad/jiayun/CS131/Project/./sample_submission/server.py", line 287, in run_forever
    server = await asyncio.start_server(self.handle_echo, self.ip, self.port)
  File "/usr/local/cs/Python-3.9.0/lib/python3.9/asyncio/streams.py", line 94, in start_server
    return await loop.create_server(factory, host, port, **kwds)
  File "/usr/local/cs/Python-3.9.0/lib/python3.9/asyncio/base_events.py", line 1494, in create_server
    raise OSError(err.errno, 'error while attempting '
OSError: [Errno 98] error while attempting to bind on address ('127.0.0.1', 12443): address already in use
Traceback (most recent call last):
  File "/w/home.27/ee/ugrad/jiayun/CS131/Project/./sample_submission/server.py", line 324, in <module>
    main()
  File "/w/home.27/ee/ugrad/jiayun/CS131/Project/./sample_submission/server.py", line 319, in main
    asyncio.run(server.run_forever())
  File "/usr/local/cs/Python-3.9.0/lib/python3.9/asyncio/runners.py", line 44, in run
    return loop.run_until_complete(main)
  File "/usr/local/cs/Python-3.9.0/lib/python3.9/asyncio/base_events.py", line 642, in run_until_complete
    return future.result()
  File "/w/home.27/ee/ugrad/jiayun/CS131/Project/./sample_submission/server.py", line 287, in run_forever
    server = await asyncio.start_server(self.handle_echo, self.ip, self.port)
  File "/usr/local/cs/Python-3.9.0/lib/python3.9/asyncio/streams.py", line 94, in start_server
    return await loop.create_server(factory, host, port, **kwds)
  File "/usr/local/cs/Python-3.9.0/lib/python3.9/asyncio/base_events.py", line 1494, in create_server
    raise OSError(err.errno, 'error while attempting '
OSError: [Errno 98] error while attempting to bind on address ('127.0.0.1', 12440): address already in use
Traceback (most recent call last):
  File "/w/home.27/ee/ugrad/jiayun/CS131/Project/./sample_submission/server.py", line 324, in <module>
    main()
  File "/w/home.27/ee/ugrad/jiayun/CS131/Project/./sample_submission/server.py", line 319, in main
    asyncio.run(server.run_forever())
  File "/usr/local/cs/Python-3.9.0/lib/python3.9/asyncio/runners.py", line 44, in run
    return loop.run_until_complete(main)
  File "/usr/local/cs/Python-3.9.0/lib/python3.9/asyncio/base_events.py", line 642, in run_until_complete
    return future.result()
  File "/w/home.27/ee/ugrad/jiayun/CS131/Project/./sample_submission/server.py", line 287, in run_forever
    server = await asyncio.start_server(self.handle_echo, self.ip, self.port)
  File "/usr/local/cs/Python-3.9.0/lib/python3.9/asyncio/streams.py", line 94, in start_server
    return await loop.create_server(factory, host, port, **kwds)
  File "/usr/local/cs/Python-3.9.0/lib/python3.9/asyncio/base_events.py", line 1494, in create_server
    raise OSError(err.errno, 'error while attempting '
OSError: [Errno 98] error while attempting to bind on address ('127.0.0.1', 12441): address already in use
Traceback (most recent call last):
  File "/w/home.27/ee/ugrad/jiayun/CS131/Project/./sample_submission/server.py", line 324, in <module>
    main()
  File "/w/home.27/ee/ugrad/jiayun/CS131/Project/./sample_submission/server.py", line 319, in main
    asyncio.run(server.run_forever())
  File "/usr/local/cs/Python-3.9.0/lib/python3.9/asyncio/runners.py", line 44, in run
    return loop.run_until_complete(main)
  File "/usr/local/cs/Python-3.9.0/lib/python3.9/asyncio/base_events.py", line 642, in run_until_complete
    return future.result()
  File "/w/home.27/ee/ugrad/jiayun/CS131/Project/./sample_submission/server.py", line 287, in run_forever
    server = await asyncio.start_server(self.handle_echo, self.ip, self.port)
  File "/usr/local/cs/Python-3.9.0/lib/python3.9/asyncio/streams.py", line 94, in start_server
    return await loop.create_server(factory, host, port, **kwds)
  File "/usr/local/cs/Python-3.9.0/lib/python3.9/asyncio/base_events.py", line 1494, in create_server
    raise OSError(err.errno, 'error while attempting '
OSError: [Errno 98] error while attempting to bind on address ('127.0.0.1', 12442): address already in use
Traceback (most recent call last):
  File "/w/home.27/ee/ugrad/jiayun/CS131/Project/./sample_submission/server.py", line 324, in <module>
    main()
  File "/w/home.27/ee/ugrad/jiayun/CS131/Project/./sample_submission/server.py", line 319, in main
    asyncio.run(server.run_forever())
  File "/usr/local/cs/Python-3.9.0/lib/python3.9/asyncio/runners.py", line 44, in run
    return loop.run_until_complete(main)
  File "/usr/local/cs/Python-3.9.0/lib/python3.9/asyncio/base_events.py", line 642, in run_until_complete
    return future.result()
  File "/w/home.27/ee/ugrad/jiayun/CS131/Project/./sample_submission/server.py", line 287, in run_forever
    server = await asyncio.start_server(self.handle_echo, self.ip, self.port)
  File "/usr/local/cs/Python-3.9.0/lib/python3.9/asyncio/streams.py", line 94, in start_server
    return await loop.create_server(factory, host, port, **kwds)
  File "/usr/local/cs/Python-3.9.0/lib/python3.9/asyncio/base_events.py", line 1494, in create_server
    raise OSError(err.errno, 'error while attempting '
OSError: [Errno 98] error while attempting to bind on address ('127.0.0.1', 12443): address already in use
Traceback (most recent call last):
  File "/w/home.27/ee/ugrad/jiayun/CS131/Project/./sample_submission/server.py", line 324, in <module>
    main()
  File "/w/home.27/ee/ugrad/jiayun/CS131/Project/./sample_submission/server.py", line 319, in main
    asyncio.run(server.run_forever())
  File "/usr/local/cs/Python-3.9.0/lib/python3.9/asyncio/runners.py", line 44, in run
    return loop.run_until_complete(main)
  File "/usr/local/cs/Python-3.9.0/lib/python3.9/asyncio/base_events.py", line 642, in run_until_complete
    return future.result()
  File "/w/home.27/ee/ugrad/jiayun/CS131/Project/./sample_submission/server.py", line 287, in run_forever
    server = await asyncio.start_server(self.handle_echo, self.ip, self.port)
  File "/usr/local/cs/Python-3.9.0/lib/python3.9/asyncio/streams.py", line 94, in start_server
    return await loop.create_server(factory, host, port, **kwds)
  File "/usr/local/cs/Python-3.9.0/lib/python3.9/asyncio/base_events.py", line 1494, in create_server
    raise OSError(err.errno, 'error while attempting '
OSError: [Errno 98] error while attempting to bind on address ('127.0.0.1', 12444): address already in use
Traceback (most recent call last):
  File "/w/home.27/ee/ugrad/jiayun/CS131/Project/./sample_submission/server.py", line 324, in <module>
    main()
  File "/w/home.27/ee/ugrad/jiayun/CS131/Project/./sample_submission/server.py", line 319, in main
    asyncio.run(server.run_forever())
  File "/usr/local/cs/Python-3.9.0/lib/python3.9/asyncio/runners.py", line 44, in run
    return loop.run_until_complete(main)
  File "/usr/local/cs/Python-3.9.0/lib/python3.9/asyncio/base_events.py", line 642, in run_until_complete
    return future.result()
  File "/w/home.27/ee/ugrad/jiayun/CS131/Project/./sample_submission/server.py", line 287, in run_forever
    server = await asyncio.start_server(self.handle_echo, self.ip, self.port)
  File "/usr/local/cs/Python-3.9.0/lib/python3.9/asyncio/streams.py", line 94, in start_server
    return await loop.create_server(factory, host, port, **kwds)
  File "/usr/local/cs/Python-3.9.0/lib/python3.9/asyncio/base_events.py", line 1494, in create_server
    raise OSError(err.errno, 'error while attempting '
OSError: [Errno 98] error while attempting to bind on address ('127.0.0.1', 12441): address already in use
Traceback (most recent call last):
  File "/w/home.27/ee/ugrad/jiayun/CS131/Project/./sample_submission/server.py", line 324, in <module>
    main()
  File "/w/home.27/ee/ugrad/jiayun/CS131/Project/./sample_submission/server.py", line 319, in main
    asyncio.run(server.run_forever())
  File "/usr/local/cs/Python-3.9.0/lib/python3.9/asyncio/runners.py", line 44, in run
    return loop.run_until_complete(main)
  File "/usr/local/cs/Python-3.9.0/lib/python3.9/asyncio/base_events.py", line 642, in run_until_complete
    return future.result()
  File "/w/home.27/ee/ugrad/jiayun/CS131/Project/./sample_submission/server.py", line 287, in run_forever
    server = await asyncio.start_server(self.handle_echo, self.ip, self.port)
  File "/usr/local/cs/Python-3.9.0/lib/python3.9/asyncio/streams.py", line 94, in start_server
    return await loop.create_server(factory, host, port, **kwds)
  File "/usr/local/cs/Python-3.9.0/lib/python3.9/asyncio/base_events.py", line 1494, in create_server
    raise OSError(err.errno, 'error while attempting '
OSError: [Errno 98] error while attempting to bind on address ('127.0.0.1', 12442): address already in use
Traceback (most recent call last):
  File "/w/home.27/ee/ugrad/jiayun/CS131/Project/./sample_submission/server.py", line 324, in <module>
    main()
  File "/w/home.27/ee/ugrad/jiayun/CS131/Project/./sample_submission/server.py", line 319, in main
    asyncio.run(server.run_forever())
  File "/usr/local/cs/Python-3.9.0/lib/python3.9/asyncio/runners.py", line 44, in run
    return loop.run_until_complete(main)
  File "/usr/local/cs/Python-3.9.0/lib/python3.9/asyncio/base_events.py", line 642, in run_until_complete
    return future.result()
  File "/w/home.27/ee/ugrad/jiayun/CS131/Project/./sample_submission/server.py", line 287, in run_forever
    server = await asyncio.start_server(self.handle_echo, self.ip, self.port)
  File "/usr/local/cs/Python-3.9.0/lib/python3.9/asyncio/streams.py", line 94, in start_server
    return await loop.create_server(factory, host, port, **kwds)
  File "/usr/local/cs/Python-3.9.0/lib/python3.9/asyncio/base_events.py", line 1494, in create_server
    raise OSError(err.errno, 'error while attempting '
OSError: [Errno 98] error while attempting to bind on address ('127.0.0.1', 12443): address already in use
Traceback (most recent call last):
  File "/w/home.27/ee/ugrad/jiayun/CS131/Project/./sample_submission/server.py", line 324, in <module>
    main()
  File "/w/home.27/ee/ugrad/jiayun/CS131/Project/./sample_submission/server.py", line 319, in main
    asyncio.run(server.run_forever())
  File "/usr/local/cs/Python-3.9.0/lib/python3.9/asyncio/runners.py", line 44, in run
    return loop.run_until_complete(main)
  File "/usr/local/cs/Python-3.9.0/lib/python3.9/asyncio/base_events.py", line 642, in run_until_complete
    return future.result()
  File "/w/home.27/ee/ugrad/jiayun/CS131/Project/./sample_submission/server.py", line 287, in run_forever
    server = await asyncio.start_server(self.handle_echo, self.ip, self.port)
  File "/usr/local/cs/Python-3.9.0/lib/python3.9/asyncio/streams.py", line 94, in start_server
    return await loop.create_server(factory, host, port, **kwds)
  File "/usr/local/cs/Python-3.9.0/lib/python3.9/asyncio/base_events.py", line 1494, in create_server
    raise OSError(err.errno, 'error while attempting '
OSError: [Errno 98] error while attempting to bind on address ('127.0.0.1', 12444): address already in use
Traceback (most recent call last):
  File "/w/home.27/ee/ugrad/jiayun/CS131/Project/./sample_submission/server.py", line 324, in <module>
    main()
  File "/w/home.27/ee/ugrad/jiayun/CS131/Project/./sample_submission/server.py", line 319, in main
    asyncio.run(server.run_forever())
  File "/usr/local/cs/Python-3.9.0/lib/python3.9/asyncio/runners.py", line 44, in run
    return loop.run_until_complete(main)
  File "/usr/local/cs/Python-3.9.0/lib/python3.9/asyncio/base_events.py", line 642, in run_until_complete
    return future.result()
  File "/w/home.27/ee/ugrad/jiayun/CS131/Project/./sample_submission/server.py", line 287, in run_forever
    server = await asyncio.start_server(self.handle_echo, self.ip, self.port)
  File "/usr/local/cs/Python-3.9.0/lib/python3.9/asyncio/streams.py", line 94, in start_server
    return await loop.create_server(factory, host, port, **kwds)
  File "/usr/local/cs/Python-3.9.0/lib/python3.9/asyncio/base_events.py", line 1494, in create_server
    raise OSError(err.errno, 'error while attempting '
OSError: [Errno 98] error while attempting to bind on address ('127.0.0.1', 12440): address already in use
Traceback (most recent call last):
  File "/w/home.27/ee/ugrad/jiayun/CS131/Project/./sample_submission/server.py", line 324, in <module>
    main()
  File "/w/home.27/ee/ugrad/jiayun/CS131/Project/./sample_submission/server.py", line 319, in main
    asyncio.run(server.run_forever())
  File "/usr/local/cs/Python-3.9.0/lib/python3.9/asyncio/runners.py", line 44, in run
    return loop.run_until_complete(main)
  File "/usr/local/cs/Python-3.9.0/lib/python3.9/asyncio/base_events.py", line 642, in run_until_complete
    return future.result()
  File "/w/home.27/ee/ugrad/jiayun/CS131/Project/./sample_submission/server.py", line 287, in run_forever
    server = await asyncio.start_server(self.handle_echo, self.ip, self.port)
  File "/usr/local/cs/Python-3.9.0/lib/python3.9/asyncio/streams.py", line 94, in start_server
    return await loop.create_server(factory, host, port, **kwds)
  File "/usr/local/cs/Python-3.9.0/lib/python3.9/asyncio/base_events.py", line 1494, in create_server
    raise OSError(err.errno, 'error while attempting '
OSError: [Errno 98] error while attempting to bind on address ('127.0.0.1', 12442): address already in use
Traceback (most recent call last):
  File "/w/home.27/ee/ugrad/jiayun/CS131/Project/./sample_submission/server.py", line 324, in <module>
    main()
  File "/w/home.27/ee/ugrad/jiayun/CS131/Project/./sample_submission/server.py", line 319, in main
    asyncio.run(server.run_forever())
  File "/usr/local/cs/Python-3.9.0/lib/python3.9/asyncio/runners.py", line 44, in run
    return loop.run_until_complete(main)
  File "/usr/local/cs/Python-3.9.0/lib/python3.9/asyncio/base_events.py", line 642, in run_until_complete
    return future.result()
  File "/w/home.27/ee/ugrad/jiayun/CS131/Project/./sample_submission/server.py", line 287, in run_forever
    server = await asyncio.start_server(self.handle_echo, self.ip, self.port)
  File "/usr/local/cs/Python-3.9.0/lib/python3.9/asyncio/streams.py", line 94, in start_server
    return await loop.create_server(factory, host, port, **kwds)
  File "/usr/local/cs/Python-3.9.0/lib/python3.9/asyncio/base_events.py", line 1494, in create_server
    raise OSError(err.errno, 'error while attempting '
OSError: [Errno 98] error while attempting to bind on address ('127.0.0.1', 12443): address already in use
Traceback (most recent call last):
  File "/w/home.27/ee/ugrad/jiayun/CS131/Project/./sample_submission/server.py", line 324, in <module>
    main()
  File "/w/home.27/ee/ugrad/jiayun/CS131/Project/./sample_submission/server.py", line 319, in main
    asyncio.run(server.run_forever())
  File "/usr/local/cs/Python-3.9.0/lib/python3.9/asyncio/runners.py", line 44, in run
    return loop.run_until_complete(main)
  File "/usr/local/cs/Python-3.9.0/lib/python3.9/asyncio/base_events.py", line 642, in run_until_complete
    return future.result()
  File "/w/home.27/ee/ugrad/jiayun/CS131/Project/./sample_submission/server.py", line 287, in run_forever
    server = await asyncio.start_server(self.handle_echo, self.ip, self.port)
  File "/usr/local/cs/Python-3.9.0/lib/python3.9/asyncio/streams.py", line 94, in start_server
    return await loop.create_server(factory, host, port, **kwds)
  File "/usr/local/cs/Python-3.9.0/lib/python3.9/asyncio/base_events.py", line 1494, in create_server
    raise OSError(err.errno, 'error while attempting '
OSError: [Errno 98] error while attempting to bind on address ('127.0.0.1', 12444): address already in use
Traceback (most recent call last):
  File "/w/home.27/ee/ugrad/jiayun/CS131/Project/./sample_submission/server.py", line 324, in <module>
    main()
  File "/w/home.27/ee/ugrad/jiayun/CS131/Project/./sample_submission/server.py", line 319, in main
    asyncio.run(server.run_forever())
  File "/usr/local/cs/Python-3.9.0/lib/python3.9/asyncio/runners.py", line 44, in run
    return loop.run_until_complete(main)
  File "/usr/local/cs/Python-3.9.0/lib/python3.9/asyncio/base_events.py", line 642, in run_until_complete
    return future.result()
  File "/w/home.27/ee/ugrad/jiayun/CS131/Project/./sample_submission/server.py", line 287, in run_forever
    server = await asyncio.start_server(self.handle_echo, self.ip, self.port)
  File "/usr/local/cs/Python-3.9.0/lib/python3.9/asyncio/streams.py", line 94, in start_server
    return await loop.create_server(factory, host, port, **kwds)
  File "/usr/local/cs/Python-3.9.0/lib/python3.9/asyncio/base_events.py", line 1494, in create_server
    raise OSError(err.errno, 'error while attempting '
OSError: [Errno 98] error while attempting to bind on address ('127.0.0.1', 12441): address already in use
Traceback (most recent call last):
  File "/w/home.27/ee/ugrad/jiayun/CS131/Project/./sample_submission/server.py", line 324, in <module>
    main()
  File "/w/home.27/ee/ugrad/jiayun/CS131/Project/./sample_submission/server.py", line 319, in main
    asyncio.run(server.run_forever())
  File "/usr/local/cs/Python-3.9.0/lib/python3.9/asyncio/runners.py", line 44, in run
    return loop.run_until_complete(main)
  File "/usr/local/cs/Python-3.9.0/lib/python3.9/asyncio/base_events.py", line 642, in run_until_complete
    return future.result()
  File "/w/home.27/ee/ugrad/jiayun/CS131/Project/./sample_submission/server.py", line 287, in run_forever
    server = await asyncio.start_server(self.handle_echo, self.ip, self.port)
  File "/usr/local/cs/Python-3.9.0/lib/python3.9/asyncio/streams.py", line 94, in start_server
    return await loop.create_server(factory, host, port, **kwds)
  File "/usr/local/cs/Python-3.9.0/lib/python3.9/asyncio/base_events.py", line 1494, in create_server
    raise OSError(err.errno, 'error while attempting '
OSError: [Errno 98] error while attempting to bind on address ('127.0.0.1', 12443): address already in use
Traceback (most recent call last):
  File "/w/home.27/ee/ugrad/jiayun/CS131/Project/./sample_submission/server.py", line 324, in <module>
    main()
  File "/w/home.27/ee/ugrad/jiayun/CS131/Project/./sample_submission/server.py", line 319, in main
    asyncio.run(server.run_forever())
  File "/usr/local/cs/Python-3.9.0/lib/python3.9/asyncio/runners.py", line 44, in run
    return loop.run_until_complete(main)
  File "/usr/local/cs/Python-3.9.0/lib/python3.9/asyncio/base_events.py", line 642, in run_until_complete
    return future.result()
  File "/w/home.27/ee/ugrad/jiayun/CS131/Project/./sample_submission/server.py", line 287, in run_forever
    server = await asyncio.start_server(self.handle_echo, self.ip, self.port)
  File "/usr/local/cs/Python-3.9.0/lib/python3.9/asyncio/streams.py", line 94, in start_server
    return await loop.create_server(factory, host, port, **kwds)
  File "/usr/local/cs/Python-3.9.0/lib/python3.9/asyncio/base_events.py", line 1494, in create_server
    raise OSError(err.errno, 'error while attempting '
OSError: [Errno 98] error while attempting to bind on address ('127.0.0.1', 12444): address already in use
Traceback (most recent call last):
  File "/w/home.27/ee/ugrad/jiayun/CS131/Project/./sample_submission/server.py", line 324, in <module>
    main()
  File "/w/home.27/ee/ugrad/jiayun/CS131/Project/./sample_submission/server.py", line 319, in main
    asyncio.run(server.run_forever())
  File "/usr/local/cs/Python-3.9.0/lib/python3.9/asyncio/runners.py", line 44, in run
    return loop.run_until_complete(main)
  File "/usr/local/cs/Python-3.9.0/lib/python3.9/asyncio/base_events.py", line 642, in run_until_complete
    return future.result()
  File "/w/home.27/ee/ugrad/jiayun/CS131/Project/./sample_submission/server.py", line 287, in run_forever
    server = await asyncio.start_server(self.handle_echo, self.ip, self.port)
  File "/usr/local/cs/Python-3.9.0/lib/python3.9/asyncio/streams.py", line 94, in start_server
    return await loop.create_server(factory, host, port, **kwds)
  File "/usr/local/cs/Python-3.9.0/lib/python3.9/asyncio/base_events.py", line 1494, in create_server
    raise OSError(err.errno, 'error while attempting '
OSError: [Errno 98] error while attempting to bind on address ('127.0.0.1', 12442): address already in use
Traceback (most recent call last):
  File "/w/home.27/ee/ugrad/jiayun/CS131/Project/./sample_submission/server.py", line 324, in <module>
    main()
  File "/w/home.27/ee/ugrad/jiayun/CS131/Project/./sample_submission/server.py", line 319, in main
    asyncio.run(server.run_forever())
  File "/usr/local/cs/Python-3.9.0/lib/python3.9/asyncio/runners.py", line 44, in run
    return loop.run_until_complete(main)
  File "/usr/local/cs/Python-3.9.0/lib/python3.9/asyncio/base_events.py", line 642, in run_until_complete
    return future.result()
  File "/w/home.27/ee/ugrad/jiayun/CS131/Project/./sample_submission/server.py", line 287, in run_forever
    server = await asyncio.start_server(self.handle_echo, self.ip, self.port)
  File "/usr/local/cs/Python-3.9.0/lib/python3.9/asyncio/streams.py", line 94, in start_server
    return await loop.create_server(factory, host, port, **kwds)
  File "/usr/local/cs/Python-3.9.0/lib/python3.9/asyncio/base_events.py", line 1494, in create_server
    raise OSError(err.errno, 'error while attempting '
OSError: [Errno 98] error while attempting to bind on address ('127.0.0.1', 12444): address already in use
Traceback (most recent call last):
  File "/w/home.27/ee/ugrad/jiayun/CS131/Project/./sample_submission/server.py", line 324, in <module>
    main()
  File "/w/home.27/ee/ugrad/jiayun/CS131/Project/./sample_submission/server.py", line 319, in main
    asyncio.run(server.run_forever())
  File "/usr/local/cs/Python-3.9.0/lib/python3.9/asyncio/runners.py", line 44, in run
    return loop.run_until_complete(main)
  File "/usr/local/cs/Python-3.9.0/lib/python3.9/asyncio/base_events.py", line 642, in run_until_complete
    return future.result()
  File "/w/home.27/ee/ugrad/jiayun/CS131/Project/./sample_submission/server.py", line 287, in run_forever
    server = await asyncio.start_server(self.handle_echo, self.ip, self.port)
  File "/usr/local/cs/Python-3.9.0/lib/python3.9/asyncio/streams.py", line 94, in start_server
    return await loop.create_server(factory, host, port, **kwds)
  File "/usr/local/cs/Python-3.9.0/lib/python3.9/asyncio/base_events.py", line 1494, in create_server
    raise OSError(err.errno, 'error while attempting '
OSError: [Errno 98] error while attempting to bind on address ('127.0.0.1', 12443): address already in use
  File "/w/home.27/ee/ugrad/jiayun/CS131/Project/./sample_submission/server.py", line 20
    "Bernard": ["Jaquez", "Juzang", "Campbell"] # Bernard talks w/ everyone but Riley
    ^
SyntaxError: invalid syntax
  File "/w/home.27/ee/ugrad/jiayun/CS131/Project/./sample_submission/server.py", line 20
    "Bernard": ["Jaquez", "Juzang", "Campbell"] # Bernard talks w/ everyone but Riley
    ^
SyntaxError: invalid syntax
  File "/w/home.27/ee/ugrad/jiayun/CS131/Project/./sample_submission/server.py", line 20
    "Bernard": ["Jaquez", "Juzang", "Campbell"] # Bernard talks w/ everyone but Riley
    ^
SyntaxError: invalid syntax
  File "/w/home.27/ee/ugrad/jiayun/CS131/Project/./sample_submission/server.py", line 20
    "Bernard": ["Jaquez", "Juzang", "Campbell"] # Bernard talks w/ everyone but Riley
    ^
SyntaxError: invalid syntax
  File "/w/home.27/ee/ugrad/jiayun/CS131/Project/./sample_submission/server.py", line 20
    "Bernard": ["Jaquez", "Juzang", "Campbell"] # Bernard talks w/ everyone but Riley
    ^
SyntaxError: invalid syntax
  File "/w/home.27/ee/ugrad/jiayun/CS131/Project/./sample_submission/server.py", line 20
    "Bernard": ["Jaquez", "Juzang", "Campbell"] # Bernard talks w/ everyone but Riley
    ^
SyntaxError: invalid syntax
  File "/w/home.27/ee/ugrad/jiayun/CS131/Project/./sample_submission/server.py", line 20
    "Bernard": ["Jaquez", "Juzang", "Campbell"] # Bernard talks w/ everyone but Riley
    ^
SyntaxError: invalid syntax
  File "/w/home.27/ee/ugrad/jiayun/CS131/Project/./sample_submission/server.py", line 20
    "Bernard": ["Jaquez", "Juzang", "Campbell"] # Bernard talks w/ everyone but Riley
    ^
SyntaxError: invalid syntax
  File "/w/home.27/ee/ugrad/jiayun/CS131/Project/./sample_submission/server.py", line 20
    "Bernard": ["Jaquez", "Juzang", "Campbell"] # Bernard talks w/ everyone but Riley
    ^
SyntaxError: invalid syntax
  File "/w/home.27/ee/ugrad/jiayun/CS131/Project/./sample_submission/server.py", line 20
    "Bernard": ["Jaquez", "Juzang", "Campbell"] # Bernard talks w/ everyone but Riley
    ^
SyntaxError: invalid syntax
  File "/w/home.27/ee/ugrad/jiayun/CS131/Project/./sample_submission/server.py", line 20
    "Bernard": ["Jaquez", "Juzang", "Campbell"] # Bernard talks w/ everyone but Riley
    ^
SyntaxError: invalid syntax
  File "/w/home.27/ee/ugrad/jiayun/CS131/Project/./sample_submission/server.py", line 20
    "Bernard": ["Jaquez", "Juzang", "Campbell"] # Bernard talks w/ everyone but Riley
    ^
SyntaxError: invalid syntax
  File "/w/home.27/ee/ugrad/jiayun/CS131/Project/./sample_submission/server.py", line 20
    "Bernard": ["Jaquez", "Juzang", "Campbell"] # Bernard talks w/ everyone but Riley
    ^
SyntaxError: invalid syntax
  File "/w/home.27/ee/ugrad/jiayun/CS131/Project/./sample_submission/server.py", line 20
    "Bernard": ["Jaquez", "Juzang", "Campbell"] # Bernard talks w/ everyone but Riley
    ^
SyntaxError: invalid syntax
  File "/w/home.27/ee/ugrad/jiayun/CS131/Project/./sample_submission/server.py", line 20
    "Bernard": ["Jaquez", "Juzang", "Campbell"] # Bernard talks w/ everyone but Riley
    ^
SyntaxError: invalid syntax
  File "/w/home.27/ee/ugrad/jiayun/CS131/Project/./sample_submission/server.py", line 20
    "Bernard": ["Jaquez", "Juzang", "Campbell"] # Bernard talks w/ everyone but Riley
    ^
SyntaxError: invalid syntax
  File "/w/home.27/ee/ugrad/jiayun/CS131/Project/./sample_submission/server.py", line 20
    "Bernard": ["Jaquez", "Juzang", "Campbell"] # Bernard talks w/ everyone but Riley
    ^
SyntaxError: invalid syntax
  File "/w/home.27/ee/ugrad/jiayun/CS131/Project/./sample_submission/server.py", line 20
    "Bernard": ["Jaquez", "Juzang", "Campbell"] # Bernard talks w/ everyone but Riley
    ^
SyntaxError: invalid syntax
  File "/w/home.27/ee/ugrad/jiayun/CS131/Project/./sample_submission/server.py", line 20
    "Bernard": ["Jaquez", "Juzang", "Campbell"] # Bernard talks w/ everyone but Riley
    ^
SyntaxError: invalid syntax
  File "/w/home.27/ee/ugrad/jiayun/CS131/Project/./sample_submission/server.py", line 20
    "Bernard": ["Jaquez", "Juzang", "Campbell"] # Bernard talks w/ everyone but Riley
    ^
SyntaxError: invalid syntax
  File "/w/home.27/ee/ugrad/jiayun/CS131/Project/./sample_submission/server.py", line 20
    "Bernard": ["Jaquez", "Juzang", "Campbell"] # Bernard talks w/ everyone but Riley
    ^
SyntaxError: invalid syntax
  File "/w/home.27/ee/ugrad/jiayun/CS131/Project/./sample_submission/server.py", line 20
    "Bernard": ["Jaquez", "Juzang", "Campbell"] # Bernard talks w/ everyone but Riley
    ^
SyntaxError: invalid syntax
  File "/w/home.27/ee/ugrad/jiayun/CS131/Project/./sample_submission/server.py", line 20
    "Bernard": ["Jaquez", "Juzang", "Campbell"] # Bernard talks w/ everyone but Riley
    ^
SyntaxError: invalid syntax
  File "/w/home.27/ee/ugrad/jiayun/CS131/Project/./sample_submission/server.py", line 20
    "Bernard": ["Jaquez", "Juzang", "Campbell"] # Bernard talks w/ everyone but Riley
    ^
SyntaxError: invalid syntax
  File "/w/home.27/ee/ugrad/jiayun/CS131/Project/./sample_submission/server.py", line 20
    "Bernard": ["Jaquez", "Juzang", "Campbell"] # Bernard talks w/ everyone but Riley
    ^
SyntaxError: invalid syntax
  File "/w/home.27/ee/ugrad/jiayun/CS131/Project/./sample_submission/server.py", line 20
    "Bernard": ["Jaquez", "Juzang", "Campbell"] # Bernard talks w/ everyone but Riley
    ^
SyntaxError: invalid syntax
  File "/w/home.27/ee/ugrad/jiayun/CS131/Project/./sample_submission/server.py", line 20
    "Bernard": ["Jaquez", "Juzang", "Campbell"] # Bernard talks w/ everyone but Riley
    ^
SyntaxError: invalid syntax
  File "/w/home.27/ee/ugrad/jiayun/CS131/Project/./sample_submission/server.py", line 20
    "Bernard": ["Jaquez", "Juzang", "Campbell"] # Bernard talks w/ everyone but Riley
    ^
SyntaxError: invalid syntax
  File "/w/home.27/ee/ugrad/jiayun/CS131/Project/./sample_submission/server.py", line 20
    "Bernard": ["Jaquez", "Juzang", "Campbell"] # Bernard talks w/ everyone but Riley
    ^
SyntaxError: invalid syntax
  File "/w/home.27/ee/ugrad/jiayun/CS131/Project/./sample_submission/server.py", line 20
    "Bernard": ["Jaquez", "Juzang", "Campbell"] # Bernard talks w/ everyone but Riley
    ^
SyntaxError: invalid syntax
  File "/w/home.27/ee/ugrad/jiayun/CS131/Project/./sample_submission/server.py", line 20
    "Bernard": ["Jaquez", "Juzang", "Campbell"] # Bernard talks w/ everyone but Riley
    ^
SyntaxError: invalid syntax
  File "/w/home.27/ee/ugrad/jiayun/CS131/Project/./sample_submission/server.py", line 20
    "Bernard": ["Jaquez", "Juzang", "Campbell"] # Bernard talks w/ everyone but Riley
    ^
SyntaxError: invalid syntax
  File "/w/home.27/ee/ugrad/jiayun/CS131/Project/./sample_submission/server.py", line 20
    "Bernard": ["Jaquez", "Juzang", "Campbell"] # Bernard talks w/ everyone but Riley
    ^
SyntaxError: invalid syntax
  File "/w/home.27/ee/ugrad/jiayun/CS131/Project/./sample_submission/server.py", line 20
    "Bernard": ["Jaquez", "Juzang", "Campbell"] # Bernard talks w/ everyone but Riley
    ^
SyntaxError: invalid syntax
  File "/w/home.27/ee/ugrad/jiayun/CS131/Project/./sample_submission/server.py", line 20
    "Bernard": ["Jaquez", "Juzang", "Campbell"] # Bernard talks w/ everyone but Riley
    ^
SyntaxError: invalid syntax
  File "/w/home.27/ee/ugrad/jiayun/CS131/Project/./sample_submission/server.py", line 20
    "Bernard": ["Jaquez", "Juzang", "Campbell"] # Bernard talks w/ everyone but Riley
    ^
SyntaxError: invalid syntax
  File "/w/home.27/ee/ugrad/jiayun/CS131/Project/./sample_submission/server.py", line 20
    "Bernard": ["Jaquez", "Juzang", "Campbell"] # Bernard talks w/ everyone but Riley
    ^
SyntaxError: invalid syntax
  File "/w/home.27/ee/ugrad/jiayun/CS131/Project/./sample_submission/server.py", line 20
    "Bernard": ["Jaquez", "Juzang", "Campbell"] # Bernard talks w/ everyone but Riley
    ^
SyntaxError: invalid syntax
  File "/w/home.27/ee/ugrad/jiayun/CS131/Project/./sample_submission/server.py", line 20
    "Bernard": ["Jaquez", "Juzang", "Campbell"] # Bernard talks w/ everyone but Riley
    ^
SyntaxError: invalid syntax
  File "/w/home.27/ee/ugrad/jiayun/CS131/Project/./sample_submission/server.py", line 20
    "Bernard": ["Jaquez", "Juzang", "Campbell"] # Bernard talks w/ everyone but Riley
    ^
SyntaxError: invalid syntax
  File "/w/home.27/ee/ugrad/jiayun/CS131/Project/./sample_submission/server.py", line 20
    "Bernard": ["Jaquez", "Juzang", "Campbell"] # Bernard talks w/ everyone but Riley
    ^
SyntaxError: invalid syntax
  File "/w/home.27/ee/ugrad/jiayun/CS131/Project/./sample_submission/server.py", line 20
    "Bernard": ["Jaquez", "Juzang", "Campbell"] # Bernard talks w/ everyone but Riley
    ^
SyntaxError: invalid syntax
  File "/w/home.27/ee/ugrad/jiayun/CS131/Project/./sample_submission/server.py", line 20
    "Bernard": ["Jaquez", "Juzang", "Campbell"] # Bernard talks w/ everyone but Riley
    ^
SyntaxError: invalid syntax
--- Logging error ---
Traceback (most recent call last):
  File "/usr/local/cs/Python-3.9.0/lib/python3.9/logging/__init__.py", line 1083, in emit
    self.flush()
  File "/usr/local/cs/Python-3.9.0/lib/python3.9/logging/__init__.py", line 1063, in flush
    self.stream.flush()
OSError: [Errno 116] Stale file handle
Call stack:
--- Logging error ---
Traceback (most recent call last):
  File "/usr/local/cs/Python-3.9.0/lib/python3.9/logging/__init__.py", line 1083, in emit
    self.flush()
  File "/usr/local/cs/Python-3.9.0/lib/python3.9/logging/__init__.py", line 1063, in flush
    self.stream.flush()
OSError: [Errno 116] Stale file handle
Call stack:
  File "/w/home.27/ee/ugrad/jiayun/CS131/Project/./sample_submission/server.py", line 324, in <module>
    main()
  File "/w/home.27/ee/ugrad/jiayun/CS131/Project/./sample_submission/server.py", line 319, in main
    asyncio.run(server.run_forever())
  File "/usr/local/cs/Python-3.9.0/lib/python3.9/asyncio/runners.py", line 44, in run
    return loop.run_until_complete(main)
  File "/usr/local/cs/Python-3.9.0/lib/python3.9/asyncio/base_events.py", line 629, in run_until_complete
    self.run_forever()
  File "/usr/local/cs/Python-3.9.0/lib/python3.9/asyncio/base_events.py", line 596, in run_forever
    self._run_once()
  File "/usr/local/cs/Python-3.9.0/lib/python3.9/asyncio/base_events.py", line 1890, in _run_once
    handle._run()
  File "/usr/local/cs/Python-3.9.0/lib/python3.9/asyncio/events.py", line 80, in _run
    self._context.run(self._callback, *self._args)
  File "/w/home.27/ee/ugrad/jiayun/CS131/Project/./sample_submission/server.py", line 189, in handle_echo
Message: 'Hill received msg AT Smith +0.0012793540954589844 client_0 +34.06893-118.445127 1622758916.5762813'
Arguments: ()
  File "/w/home.27/ee/ugrad/jiayun/CS131/Project/./sample_submission/server.py", line 324, in <module>
    main()
  File "/w/home.27/ee/ugrad/jiayun/CS131/Project/./sample_submission/server.py", line 319, in main
    asyncio.run(server.run_forever())
  File "/usr/local/cs/Python-3.9.0/lib/python3.9/asyncio/runners.py", line 44, in run
    return loop.run_until_complete(main)
  File "/usr/local/cs/Python-3.9.0/lib/python3.9/asyncio/base_events.py", line 629, in run_until_complete
    self.run_forever()
  File "/usr/local/cs/Python-3.9.0/lib/python3.9/asyncio/base_events.py", line 596, in run_forever
    self._run_once()
  File "/usr/local/cs/Python-3.9.0/lib/python3.9/asyncio/base_events.py", line 1890, in _run_once
    handle._run()
  File "/usr/local/cs/Python-3.9.0/lib/python3.9/asyncio/events.py", line 80, in _run
    self._context.run(self._callback, *self._args)
  File "/w/home.27/ee/ugrad/jiayun/CS131/Project/./sample_submission/server.py", line 189, in handle_echo
Message: 'Jaquez received msg AT Smith +0.0012793540954589844 client_0 +34.06893-118.445127 1622758916.5762813'
Arguments: ()
  File "/w/home.27/ee/ugrad/jiayun/CS131/Project/./sample_submission/server.py", line 20
    "Bernard": ["Jaquez", "Juzang", "Campbell"] # Bernard talks w/ everyone but Riley
    ^
SyntaxError: invalid syntax
  File "/w/home.27/ee/ugrad/jiayun/CS131/Project/./sample_submission/server.py", line 20
    "Bernard": ["Jaquez", "Juzang", "Campbell"] # Bernard talks w/ everyone but Riley
    ^
SyntaxError: invalid syntax
--- Logging error ---
Traceback (most recent call last):
  File "/usr/local/cs/Python-3.9.0/lib/python3.9/logging/__init__.py", line 1083, in emit
    self.flush()
  File "/usr/local/cs/Python-3.9.0/lib/python3.9/logging/__init__.py", line 1063, in flush
    self.stream.flush()
OSError: [Errno 116] Stale file handle
Call stack:
  File "/w/home.27/ee/ugrad/jiayun/CS131/Project/./sample_submission/server.py", line 324, in <module>
    main()
  File "/w/home.27/ee/ugrad/jiayun/CS131/Project/./sample_submission/server.py", line 319, in main
    asyncio.run(server.run_forever())
  File "/usr/local/cs/Python-3.9.0/lib/python3.9/asyncio/runners.py", line 44, in run
    return loop.run_until_complete(main)
  File "/usr/local/cs/Python-3.9.0/lib/python3.9/asyncio/base_events.py", line 629, in run_until_complete
    self.run_forever()
  File "/usr/local/cs/Python-3.9.0/lib/python3.9/asyncio/base_events.py", line 596, in run_forever
    self._run_once()
  File "/usr/local/cs/Python-3.9.0/lib/python3.9/asyncio/base_events.py", line 1890, in _run_once
    handle._run()
  File "/usr/local/cs/Python-3.9.0/lib/python3.9/asyncio/events.py", line 80, in _run
    self._context.run(self._callback, *self._args)
  File "/w/home.27/ee/ugrad/jiayun/CS131/Project/./sample_submission/server.py", line 189, in handle_echo
Message: 'Jaquez received msg IAMAT client_0 +34.06893-118.445127 1622758925.1282492\n'
Arguments: ()
--- Logging error ---
Traceback (most recent call last):
  File "/usr/local/cs/Python-3.9.0/lib/python3.9/logging/__init__.py", line 1083, in emit
    self.flush()
  File "/usr/local/cs/Python-3.9.0/lib/python3.9/logging/__init__.py", line 1063, in flush
    self.stream.flush()
OSError: [Errno 116] Stale file handle
Call stack:
  File "/w/home.27/ee/ugrad/jiayun/CS131/Project/./sample_submission/server.py", line 324, in <module>
    main()
  File "/w/home.27/ee/ugrad/jiayun/CS131/Project/./sample_submission/server.py", line 319, in main
    asyncio.run(server.run_forever())
  File "/usr/local/cs/Python-3.9.0/lib/python3.9/asyncio/runners.py", line 44, in run
    return loop.run_until_complete(main)
  File "/usr/local/cs/Python-3.9.0/lib/python3.9/asyncio/base_events.py", line 629, in run_until_complete
    self.run_forever()
  File "/usr/local/cs/Python-3.9.0/lib/python3.9/asyncio/base_events.py", line 596, in run_forever
    self._run_once()
  File "/usr/local/cs/Python-3.9.0/lib/python3.9/asyncio/base_events.py", line 1890, in _run_once
    handle._run()
  File "/usr/local/cs/Python-3.9.0/lib/python3.9/asyncio/events.py", line 80, in _run
    self._context.run(self._callback, *self._args)
  File "/w/home.27/ee/ugrad/jiayun/CS131/Project/./sample_submission/server.py", line 189, in handle_echo
Message: 'Hill received msg AT Jaquez +0.0030744075775146484 client_0 +34.06893-118.445127 1622758925.1282492'
Arguments: ()
  File "/w/home.27/ee/ugrad/jiayun/CS131/Project/./sample_submission/server.py", line 20
    "Bernard": ["Jaquez", "Juzang", "Campbell"] # Bernard talks w/ everyone but Riley
    ^
SyntaxError: invalid syntax
  File "/w/home.27/ee/ugrad/jiayun/CS131/Project/./sample_submission/server.py", line 20
    "Bernard": ["Jaquez", "Juzang", "Campbell"] # Bernard talks w/ everyone but Riley
    ^
SyntaxError: invalid syntax
  File "/w/home.27/ee/ugrad/jiayun/CS131/Project/./sample_submission/server.py", line 20
    "Bernard": ["Jaquez", "Juzang", "Campbell"] # Bernard talks w/ everyone but Riley
    ^
SyntaxError: invalid syntax
  File "/w/home.27/ee/ugrad/jiayun/CS131/Project/./sample_submission/server.py", line 20
    "Bernard": ["Jaquez", "Juzang", "Campbell"] # Bernard talks w/ everyone but Riley
    ^
SyntaxError: invalid syntax
  File "/w/home.27/ee/ugrad/jiayun/CS131/Project/./sample_submission/server.py", line 20
    "Bernard": ["Jaquez", "Juzang", "Campbell"] # Bernard talks w/ everyone but Riley
    ^
SyntaxError: invalid syntax
  File "/w/home.27/ee/ugrad/jiayun/CS131/Project/./sample_submission/server.py", line 20
    "Bernard": ["Jaquez", "Juzang", "Campbell"] # Bernard talks w/ everyone but Riley
    ^
SyntaxError: invalid syntax
  File "/w/home.27/ee/ugrad/jiayun/CS131/Project/./sample_submission/server.py", line 20
    "Bernard": ["Jaquez", "Juzang", "Campbell"] # Bernard talks w/ everyone but Riley
    ^
SyntaxError: invalid syntax
  File "/w/home.27/ee/ugrad/jiayun/CS131/Project/./sample_submission/server.py", line 20
    "Bernard": ["Jaquez", "Juzang", "Campbell"] # Bernard talks w/ everyone but Riley
    ^
SyntaxError: invalid syntax
--- Logging error ---
Traceback (most recent call last):
  File "/usr/local/cs/Python-3.9.0/lib/python3.9/logging/__init__.py", line 1083, in emit
    self.flush()
  File "/usr/local/cs/Python-3.9.0/lib/python3.9/logging/__init__.py", line 1063, in flush
    self.stream.flush()
OSError: [Errno 116] Stale file handle
Call stack:
  File "/w/home.27/ee/ugrad/jiayun/CS131/Project/./sample_submission/server.py", line 324, in <module>
    main()
  File "/w/home.27/ee/ugrad/jiayun/CS131/Project/./sample_submission/server.py", line 319, in main
    asyncio.run(server.run_forever())
  File "/usr/local/cs/Python-3.9.0/lib/python3.9/asyncio/runners.py", line 44, in run
    return loop.run_until_complete(main)
  File "/usr/local/cs/Python-3.9.0/lib/python3.9/asyncio/base_events.py", line 629, in run_until_complete
    self.run_forever()
  File "/usr/local/cs/Python-3.9.0/lib/python3.9/asyncio/base_events.py", line 596, in run_forever
    self._run_once()
  File "/usr/local/cs/Python-3.9.0/lib/python3.9/asyncio/base_events.py", line 1890, in _run_once
    handle._run()
  File "/usr/local/cs/Python-3.9.0/lib/python3.9/asyncio/events.py", line 80, in _run
    self._context.run(self._callback, *self._args)
  File "/w/home.27/ee/ugrad/jiayun/CS131/Project/./sample_submission/server.py", line 189, in handle_echo
Message: 'Hill received msg IAMAT client_2 +34.06893-118.445127 1622758958.7482681\n'
Arguments: ()
--- Logging error ---
Traceback (most recent call last):
  File "/usr/local/cs/Python-3.9.0/lib/python3.9/logging/__init__.py", line 1083, in emit
    self.flush()
  File "/usr/local/cs/Python-3.9.0/lib/python3.9/logging/__init__.py", line 1063, in flush
    self.stream.flush()
OSError: [Errno 116] Stale file handle
Call stack:
  File "/w/home.27/ee/ugrad/jiayun/CS131/Project/./sample_submission/server.py", line 324, in <module>
    main()
  File "/w/home.27/ee/ugrad/jiayun/CS131/Project/./sample_submission/server.py", line 319, in main
    asyncio.run(server.run_forever())
  File "/usr/local/cs/Python-3.9.0/lib/python3.9/asyncio/runners.py", line 44, in run
    return loop.run_until_complete(main)
  File "/usr/local/cs/Python-3.9.0/lib/python3.9/asyncio/base_events.py", line 629, in run_until_complete
    self.run_forever()
  File "/usr/local/cs/Python-3.9.0/lib/python3.9/asyncio/base_events.py", line 596, in run_forever
    self._run_once()
  File "/usr/local/cs/Python-3.9.0/lib/python3.9/asyncio/base_events.py", line 1890, in _run_once
    handle._run()
  File "/usr/local/cs/Python-3.9.0/lib/python3.9/asyncio/events.py", line 80, in _run
    self._context.run(self._callback, *self._args)
  File "/w/home.27/ee/ugrad/jiayun/CS131/Project/./sample_submission/server.py", line 189, in handle_echo
Message: 'Jaquez received msg AT Hill +0.0027933120727539062 client_2 +34.06893-118.445127 1622758958.7482681'
Arguments: ()
  File "/w/home.27/ee/ugrad/jiayun/CS131/Project/./sample_submission/server.py", line 20
    "Bernard": ["Jaquez", "Juzang", "Campbell"] # Bernard talks w/ everyone but Riley
    ^
SyntaxError: invalid syntax
  File "/w/home.27/ee/ugrad/jiayun/CS131/Project/./sample_submission/server.py", line 20
    "Bernard": ["Jaquez", "Juzang", "Campbell"] # Bernard talks w/ everyone but Riley
    ^
SyntaxError: invalid syntax
  File "/w/home.27/ee/ugrad/jiayun/CS131/Project/./sample_submission/server.py", line 20
    "Bernard": ["Jaquez", "Juzang", "Campbell"] # Bernard talks w/ everyone but Riley
    ^
SyntaxError: invalid syntax
  File "/w/home.27/ee/ugrad/jiayun/CS131/Project/./sample_submission/server.py", line 20
    "Bernard": ["Jaquez", "Juzang", "Campbell"] # Bernard talks w/ everyone but Riley
    ^
SyntaxError: invalid syntax
